ERROR 2016-03-23 15:17:43,993 base 16689 140675361544000 Internal Server Error: /newsite
Traceback (most recent call last):
  File "/usr/local/lib/python2.7/dist-packages/django/core/handlers/base.py", line 149, in get_response
    response = self.process_exception_by_middleware(e, request)
  File "/usr/local/lib/python2.7/dist-packages/django/core/handlers/base.py", line 147, in get_response
    response = wrapped_callback(request, *callback_args, **callback_kwargs)
  File "/opt/nbproject/apps/pages/views.py", line 172, in newsite
    if user_form.is_valid() and ensemble_form.is_valid():
  File "/usr/local/lib/python2.7/dist-packages/django/forms/forms.py", line 161, in is_valid
    return self.is_bound and not self.errors
  File "/usr/local/lib/python2.7/dist-packages/django/forms/forms.py", line 153, in errors
    self.full_clean()
  File "/usr/local/lib/python2.7/dist-packages/django/forms/forms.py", line 364, in full_clean
    self._post_clean()
  File "/usr/local/lib/python2.7/dist-packages/django/forms/models.py", line 402, in _post_clean
    self.validate_unique()
  File "/usr/local/lib/python2.7/dist-packages/django/forms/models.py", line 411, in validate_unique
    self.instance.validate_unique(exclude=exclude)
  File "/usr/local/lib/python2.7/dist-packages/django/db/models/base.py", line 922, in validate_unique
    errors = self._perform_unique_checks(unique_checks)
  File "/usr/local/lib/python2.7/dist-packages/django/db/models/base.py", line 1017, in _perform_unique_checks
    if qs.exists():
  File "/usr/local/lib/python2.7/dist-packages/django/db/models/query.py", line 651, in exists
    return self.query.has_results(using=self.db)
  File "/usr/local/lib/python2.7/dist-packages/django/db/models/sql/query.py", line 501, in has_results
    return compiler.has_results()
  File "/usr/local/lib/python2.7/dist-packages/django/db/models/sql/compiler.py", line 819, in has_results
    return bool(self.execute_sql(SINGLE))
  File "/usr/local/lib/python2.7/dist-packages/django/db/models/sql/compiler.py", line 848, in execute_sql
    cursor.execute(sql, params)
  File "/usr/local/lib/python2.7/dist-packages/django/db/backends/utils.py", line 64, in execute
    return self.cursor.execute(sql, params)
  File "/usr/local/lib/python2.7/dist-packages/django/db/utils.py", line 95, in __exit__
    six.reraise(dj_exc_type, dj_exc_value, traceback)
  File "/usr/local/lib/python2.7/dist-packages/django/db/backends/utils.py", line 64, in execute
    return self.cursor.execute(sql, params)
ProgrammingError: relation "base_user" does not exist
LINE 1: SELECT (1) AS "a" FROM "base_user" WHERE "base_user"."email"...
                               ^

ERROR 2016-03-23 15:18:01,567 base 16689 140675361544000 Internal Server Error: /newsite
Traceback (most recent call last):
  File "/usr/local/lib/python2.7/dist-packages/django/core/handlers/base.py", line 149, in get_response
    response = self.process_exception_by_middleware(e, request)
  File "/usr/local/lib/python2.7/dist-packages/django/core/handlers/base.py", line 147, in get_response
    response = wrapped_callback(request, *callback_args, **callback_kwargs)
  File "/opt/nbproject/apps/pages/views.py", line 172, in newsite
    if user_form.is_valid() and ensemble_form.is_valid():
  File "/usr/local/lib/python2.7/dist-packages/django/forms/forms.py", line 161, in is_valid
    return self.is_bound and not self.errors
  File "/usr/local/lib/python2.7/dist-packages/django/forms/forms.py", line 153, in errors
    self.full_clean()
  File "/usr/local/lib/python2.7/dist-packages/django/forms/forms.py", line 364, in full_clean
    self._post_clean()
  File "/usr/local/lib/python2.7/dist-packages/django/forms/models.py", line 402, in _post_clean
    self.validate_unique()
  File "/usr/local/lib/python2.7/dist-packages/django/forms/models.py", line 411, in validate_unique
    self.instance.validate_unique(exclude=exclude)
  File "/usr/local/lib/python2.7/dist-packages/django/db/models/base.py", line 922, in validate_unique
    errors = self._perform_unique_checks(unique_checks)
  File "/usr/local/lib/python2.7/dist-packages/django/db/models/base.py", line 1017, in _perform_unique_checks
    if qs.exists():
  File "/usr/local/lib/python2.7/dist-packages/django/db/models/query.py", line 651, in exists
    return self.query.has_results(using=self.db)
  File "/usr/local/lib/python2.7/dist-packages/django/db/models/sql/query.py", line 501, in has_results
    return compiler.has_results()
  File "/usr/local/lib/python2.7/dist-packages/django/db/models/sql/compiler.py", line 819, in has_results
    return bool(self.execute_sql(SINGLE))
  File "/usr/local/lib/python2.7/dist-packages/django/db/models/sql/compiler.py", line 848, in execute_sql
    cursor.execute(sql, params)
  File "/usr/local/lib/python2.7/dist-packages/django/db/backends/utils.py", line 64, in execute
    return self.cursor.execute(sql, params)
  File "/usr/local/lib/python2.7/dist-packages/django/db/utils.py", line 95, in __exit__
    six.reraise(dj_exc_type, dj_exc_value, traceback)
  File "/usr/local/lib/python2.7/dist-packages/django/db/backends/utils.py", line 64, in execute
    return self.cursor.execute(sql, params)
ProgrammingError: relation "base_user" does not exist
LINE 1: SELECT (1) AS "a" FROM "base_user" WHERE "base_user"."email"...
                               ^

ERROR 2016-03-23 15:18:21,945 base 16689 140675361544000 Internal Server Error: /newsite
Traceback (most recent call last):
  File "/usr/local/lib/python2.7/dist-packages/django/core/handlers/base.py", line 149, in get_response
    response = self.process_exception_by_middleware(e, request)
  File "/usr/local/lib/python2.7/dist-packages/django/core/handlers/base.py", line 147, in get_response
    response = wrapped_callback(request, *callback_args, **callback_kwargs)
  File "/opt/nbproject/apps/pages/views.py", line 172, in newsite
    if user_form.is_valid() and ensemble_form.is_valid():
  File "/usr/local/lib/python2.7/dist-packages/django/forms/forms.py", line 161, in is_valid
    return self.is_bound and not self.errors
  File "/usr/local/lib/python2.7/dist-packages/django/forms/forms.py", line 153, in errors
    self.full_clean()
  File "/usr/local/lib/python2.7/dist-packages/django/forms/forms.py", line 364, in full_clean
    self._post_clean()
  File "/usr/local/lib/python2.7/dist-packages/django/forms/models.py", line 402, in _post_clean
    self.validate_unique()
  File "/usr/local/lib/python2.7/dist-packages/django/forms/models.py", line 411, in validate_unique
    self.instance.validate_unique(exclude=exclude)
  File "/usr/local/lib/python2.7/dist-packages/django/db/models/base.py", line 922, in validate_unique
    errors = self._perform_unique_checks(unique_checks)
  File "/usr/local/lib/python2.7/dist-packages/django/db/models/base.py", line 1017, in _perform_unique_checks
    if qs.exists():
  File "/usr/local/lib/python2.7/dist-packages/django/db/models/query.py", line 651, in exists
    return self.query.has_results(using=self.db)
  File "/usr/local/lib/python2.7/dist-packages/django/db/models/sql/query.py", line 501, in has_results
    return compiler.has_results()
  File "/usr/local/lib/python2.7/dist-packages/django/db/models/sql/compiler.py", line 819, in has_results
    return bool(self.execute_sql(SINGLE))
  File "/usr/local/lib/python2.7/dist-packages/django/db/models/sql/compiler.py", line 848, in execute_sql
    cursor.execute(sql, params)
  File "/usr/local/lib/python2.7/dist-packages/django/db/backends/utils.py", line 64, in execute
    return self.cursor.execute(sql, params)
  File "/usr/local/lib/python2.7/dist-packages/django/db/utils.py", line 95, in __exit__
    six.reraise(dj_exc_type, dj_exc_value, traceback)
  File "/usr/local/lib/python2.7/dist-packages/django/db/backends/utils.py", line 64, in execute
    return self.cursor.execute(sql, params)
ProgrammingError: relation "base_user" does not exist
LINE 1: SELECT (1) AS "a" FROM "base_user" WHERE "base_user"."email"...
                               ^

ERROR 2016-03-23 15:19:19,818 base 16689 140675361544000 Internal Server Error: /newsite
Traceback (most recent call last):
  File "/usr/local/lib/python2.7/dist-packages/django/core/handlers/base.py", line 149, in get_response
    response = self.process_exception_by_middleware(e, request)
  File "/usr/local/lib/python2.7/dist-packages/django/core/handlers/base.py", line 147, in get_response
    response = wrapped_callback(request, *callback_args, **callback_kwargs)
  File "/opt/nbproject/apps/pages/views.py", line 172, in newsite
    if user_form.is_valid() and ensemble_form.is_valid():
  File "/usr/local/lib/python2.7/dist-packages/django/forms/forms.py", line 161, in is_valid
    return self.is_bound and not self.errors
  File "/usr/local/lib/python2.7/dist-packages/django/forms/forms.py", line 153, in errors
    self.full_clean()
  File "/usr/local/lib/python2.7/dist-packages/django/forms/forms.py", line 364, in full_clean
    self._post_clean()
  File "/usr/local/lib/python2.7/dist-packages/django/forms/models.py", line 402, in _post_clean
    self.validate_unique()
  File "/usr/local/lib/python2.7/dist-packages/django/forms/models.py", line 411, in validate_unique
    self.instance.validate_unique(exclude=exclude)
  File "/usr/local/lib/python2.7/dist-packages/django/db/models/base.py", line 922, in validate_unique
    errors = self._perform_unique_checks(unique_checks)
  File "/usr/local/lib/python2.7/dist-packages/django/db/models/base.py", line 1017, in _perform_unique_checks
    if qs.exists():
  File "/usr/local/lib/python2.7/dist-packages/django/db/models/query.py", line 651, in exists
    return self.query.has_results(using=self.db)
  File "/usr/local/lib/python2.7/dist-packages/django/db/models/sql/query.py", line 501, in has_results
    return compiler.has_results()
  File "/usr/local/lib/python2.7/dist-packages/django/db/models/sql/compiler.py", line 819, in has_results
    return bool(self.execute_sql(SINGLE))
  File "/usr/local/lib/python2.7/dist-packages/django/db/models/sql/compiler.py", line 848, in execute_sql
    cursor.execute(sql, params)
  File "/usr/local/lib/python2.7/dist-packages/django/db/backends/utils.py", line 64, in execute
    return self.cursor.execute(sql, params)
  File "/usr/local/lib/python2.7/dist-packages/django/db/utils.py", line 95, in __exit__
    six.reraise(dj_exc_type, dj_exc_value, traceback)
  File "/usr/local/lib/python2.7/dist-packages/django/db/backends/utils.py", line 64, in execute
    return self.cursor.execute(sql, params)
ProgrammingError: relation "base_user" does not exist
LINE 1: SELECT (1) AS "a" FROM "base_user" WHERE "base_user"."email"...
                               ^

ERROR 2016-03-23 15:19:24,488 base 16689 140675361544000 Internal Server Error: /newsite
Traceback (most recent call last):
  File "/usr/local/lib/python2.7/dist-packages/django/core/handlers/base.py", line 149, in get_response
    response = self.process_exception_by_middleware(e, request)
  File "/usr/local/lib/python2.7/dist-packages/django/core/handlers/base.py", line 147, in get_response
    response = wrapped_callback(request, *callback_args, **callback_kwargs)
  File "/opt/nbproject/apps/pages/views.py", line 172, in newsite
    if user_form.is_valid() and ensemble_form.is_valid():
  File "/usr/local/lib/python2.7/dist-packages/django/forms/forms.py", line 161, in is_valid
    return self.is_bound and not self.errors
  File "/usr/local/lib/python2.7/dist-packages/django/forms/forms.py", line 153, in errors
    self.full_clean()
  File "/usr/local/lib/python2.7/dist-packages/django/forms/forms.py", line 364, in full_clean
    self._post_clean()
  File "/usr/local/lib/python2.7/dist-packages/django/forms/models.py", line 402, in _post_clean
    self.validate_unique()
  File "/usr/local/lib/python2.7/dist-packages/django/forms/models.py", line 411, in validate_unique
    self.instance.validate_unique(exclude=exclude)
  File "/usr/local/lib/python2.7/dist-packages/django/db/models/base.py", line 922, in validate_unique
    errors = self._perform_unique_checks(unique_checks)
  File "/usr/local/lib/python2.7/dist-packages/django/db/models/base.py", line 1017, in _perform_unique_checks
    if qs.exists():
  File "/usr/local/lib/python2.7/dist-packages/django/db/models/query.py", line 651, in exists
    return self.query.has_results(using=self.db)
  File "/usr/local/lib/python2.7/dist-packages/django/db/models/sql/query.py", line 501, in has_results
    return compiler.has_results()
  File "/usr/local/lib/python2.7/dist-packages/django/db/models/sql/compiler.py", line 819, in has_results
    return bool(self.execute_sql(SINGLE))
  File "/usr/local/lib/python2.7/dist-packages/django/db/models/sql/compiler.py", line 848, in execute_sql
    cursor.execute(sql, params)
  File "/usr/local/lib/python2.7/dist-packages/django/db/backends/utils.py", line 64, in execute
    return self.cursor.execute(sql, params)
  File "/usr/local/lib/python2.7/dist-packages/django/db/utils.py", line 95, in __exit__
    six.reraise(dj_exc_type, dj_exc_value, traceback)
  File "/usr/local/lib/python2.7/dist-packages/django/db/backends/utils.py", line 64, in execute
    return self.cursor.execute(sql, params)
ProgrammingError: relation "base_user" does not exist
LINE 1: SELECT (1) AS "a" FROM "base_user" WHERE "base_user"."email"...
                               ^

ERROR 2016-03-23 15:19:53,399 base 16689 140675361544000 Internal Server Error: /newsite
Traceback (most recent call last):
  File "/usr/local/lib/python2.7/dist-packages/django/core/handlers/base.py", line 149, in get_response
    response = self.process_exception_by_middleware(e, request)
  File "/usr/local/lib/python2.7/dist-packages/django/core/handlers/base.py", line 147, in get_response
    response = wrapped_callback(request, *callback_args, **callback_kwargs)
  File "/opt/nbproject/apps/pages/views.py", line 172, in newsite
    if user_form.is_valid() and ensemble_form.is_valid():
  File "/usr/local/lib/python2.7/dist-packages/django/forms/forms.py", line 161, in is_valid
    return self.is_bound and not self.errors
  File "/usr/local/lib/python2.7/dist-packages/django/forms/forms.py", line 153, in errors
    self.full_clean()
  File "/usr/local/lib/python2.7/dist-packages/django/forms/forms.py", line 364, in full_clean
    self._post_clean()
  File "/usr/local/lib/python2.7/dist-packages/django/forms/models.py", line 402, in _post_clean
    self.validate_unique()
  File "/usr/local/lib/python2.7/dist-packages/django/forms/models.py", line 411, in validate_unique
    self.instance.validate_unique(exclude=exclude)
  File "/usr/local/lib/python2.7/dist-packages/django/db/models/base.py", line 922, in validate_unique
    errors = self._perform_unique_checks(unique_checks)
  File "/usr/local/lib/python2.7/dist-packages/django/db/models/base.py", line 1017, in _perform_unique_checks
    if qs.exists():
  File "/usr/local/lib/python2.7/dist-packages/django/db/models/query.py", line 651, in exists
    return self.query.has_results(using=self.db)
  File "/usr/local/lib/python2.7/dist-packages/django/db/models/sql/query.py", line 501, in has_results
    return compiler.has_results()
  File "/usr/local/lib/python2.7/dist-packages/django/db/models/sql/compiler.py", line 819, in has_results
    return bool(self.execute_sql(SINGLE))
  File "/usr/local/lib/python2.7/dist-packages/django/db/models/sql/compiler.py", line 848, in execute_sql
    cursor.execute(sql, params)
  File "/usr/local/lib/python2.7/dist-packages/django/db/backends/utils.py", line 64, in execute
    return self.cursor.execute(sql, params)
  File "/usr/local/lib/python2.7/dist-packages/django/db/utils.py", line 95, in __exit__
    six.reraise(dj_exc_type, dj_exc_value, traceback)
  File "/usr/local/lib/python2.7/dist-packages/django/db/backends/utils.py", line 64, in execute
    return self.cursor.execute(sql, params)
ProgrammingError: relation "base_user" does not exist
LINE 1: SELECT (1) AS "a" FROM "base_user" WHERE "base_user"."email"...
                               ^

ERROR 2016-03-23 15:19:59,699 base 16689 140675361544000 Internal Server Error: /newsite
Traceback (most recent call last):
  File "/usr/local/lib/python2.7/dist-packages/django/core/handlers/base.py", line 149, in get_response
    response = self.process_exception_by_middleware(e, request)
  File "/usr/local/lib/python2.7/dist-packages/django/core/handlers/base.py", line 147, in get_response
    response = wrapped_callback(request, *callback_args, **callback_kwargs)
  File "/opt/nbproject/apps/pages/views.py", line 172, in newsite
    if user_form.is_valid() and ensemble_form.is_valid():
  File "/usr/local/lib/python2.7/dist-packages/django/forms/forms.py", line 161, in is_valid
    return self.is_bound and not self.errors
  File "/usr/local/lib/python2.7/dist-packages/django/forms/forms.py", line 153, in errors
    self.full_clean()
  File "/usr/local/lib/python2.7/dist-packages/django/forms/forms.py", line 364, in full_clean
    self._post_clean()
  File "/usr/local/lib/python2.7/dist-packages/django/forms/models.py", line 402, in _post_clean
    self.validate_unique()
  File "/usr/local/lib/python2.7/dist-packages/django/forms/models.py", line 411, in validate_unique
    self.instance.validate_unique(exclude=exclude)
  File "/usr/local/lib/python2.7/dist-packages/django/db/models/base.py", line 922, in validate_unique
    errors = self._perform_unique_checks(unique_checks)
  File "/usr/local/lib/python2.7/dist-packages/django/db/models/base.py", line 1017, in _perform_unique_checks
    if qs.exists():
  File "/usr/local/lib/python2.7/dist-packages/django/db/models/query.py", line 651, in exists
    return self.query.has_results(using=self.db)
  File "/usr/local/lib/python2.7/dist-packages/django/db/models/sql/query.py", line 501, in has_results
    return compiler.has_results()
  File "/usr/local/lib/python2.7/dist-packages/django/db/models/sql/compiler.py", line 819, in has_results
    return bool(self.execute_sql(SINGLE))
  File "/usr/local/lib/python2.7/dist-packages/django/db/models/sql/compiler.py", line 848, in execute_sql
    cursor.execute(sql, params)
  File "/usr/local/lib/python2.7/dist-packages/django/db/backends/utils.py", line 64, in execute
    return self.cursor.execute(sql, params)
  File "/usr/local/lib/python2.7/dist-packages/django/db/utils.py", line 95, in __exit__
    six.reraise(dj_exc_type, dj_exc_value, traceback)
  File "/usr/local/lib/python2.7/dist-packages/django/db/backends/utils.py", line 64, in execute
    return self.cursor.execute(sql, params)
ProgrammingError: relation "base_user" does not exist
LINE 1: SELECT (1) AS "a" FROM "base_user" WHERE "base_user"."email"...
                               ^

ERROR 2016-03-23 15:22:03,753 base 17320 140127728568128 Internal Server Error: /newsite
Traceback (most recent call last):
  File "/usr/local/lib/python2.7/dist-packages/django/core/handlers/base.py", line 149, in get_response
    response = self.process_exception_by_middleware(e, request)
  File "/usr/local/lib/python2.7/dist-packages/django/core/handlers/base.py", line 147, in get_response
    response = wrapped_callback(request, *callback_args, **callback_kwargs)
  File "/opt/nbproject/apps/pages/views.py", line 172, in newsite
    if user_form.is_valid() and ensemble_form.is_valid():
  File "/usr/local/lib/python2.7/dist-packages/django/forms/forms.py", line 161, in is_valid
    return self.is_bound and not self.errors
  File "/usr/local/lib/python2.7/dist-packages/django/forms/forms.py", line 153, in errors
    self.full_clean()
  File "/usr/local/lib/python2.7/dist-packages/django/forms/forms.py", line 364, in full_clean
    self._post_clean()
  File "/usr/local/lib/python2.7/dist-packages/django/forms/models.py", line 402, in _post_clean
    self.validate_unique()
  File "/usr/local/lib/python2.7/dist-packages/django/forms/models.py", line 411, in validate_unique
    self.instance.validate_unique(exclude=exclude)
  File "/usr/local/lib/python2.7/dist-packages/django/db/models/base.py", line 922, in validate_unique
    errors = self._perform_unique_checks(unique_checks)
  File "/usr/local/lib/python2.7/dist-packages/django/db/models/base.py", line 1017, in _perform_unique_checks
    if qs.exists():
  File "/usr/local/lib/python2.7/dist-packages/django/db/models/query.py", line 651, in exists
    return self.query.has_results(using=self.db)
  File "/usr/local/lib/python2.7/dist-packages/django/db/models/sql/query.py", line 501, in has_results
    return compiler.has_results()
  File "/usr/local/lib/python2.7/dist-packages/django/db/models/sql/compiler.py", line 819, in has_results
    return bool(self.execute_sql(SINGLE))
  File "/usr/local/lib/python2.7/dist-packages/django/db/models/sql/compiler.py", line 848, in execute_sql
    cursor.execute(sql, params)
  File "/usr/local/lib/python2.7/dist-packages/django/db/backends/utils.py", line 64, in execute
    return self.cursor.execute(sql, params)
  File "/usr/local/lib/python2.7/dist-packages/django/db/utils.py", line 95, in __exit__
    six.reraise(dj_exc_type, dj_exc_value, traceback)
  File "/usr/local/lib/python2.7/dist-packages/django/db/backends/utils.py", line 64, in execute
    return self.cursor.execute(sql, params)
ProgrammingError: relation "base_user" does not exist
LINE 1: SELECT (1) AS "a" FROM "base_user" WHERE "base_user"."email"...
                               ^

ERROR 2016-03-23 15:22:16,111 base 17320 140127728568128 Internal Server Error: /newsite
Traceback (most recent call last):
  File "/usr/local/lib/python2.7/dist-packages/django/core/handlers/base.py", line 149, in get_response
    response = self.process_exception_by_middleware(e, request)
  File "/usr/local/lib/python2.7/dist-packages/django/core/handlers/base.py", line 147, in get_response
    response = wrapped_callback(request, *callback_args, **callback_kwargs)
  File "/opt/nbproject/apps/pages/views.py", line 172, in newsite
    if user_form.is_valid() and ensemble_form.is_valid():
  File "/usr/local/lib/python2.7/dist-packages/django/forms/forms.py", line 161, in is_valid
    return self.is_bound and not self.errors
  File "/usr/local/lib/python2.7/dist-packages/django/forms/forms.py", line 153, in errors
    self.full_clean()
  File "/usr/local/lib/python2.7/dist-packages/django/forms/forms.py", line 364, in full_clean
    self._post_clean()
  File "/usr/local/lib/python2.7/dist-packages/django/forms/models.py", line 402, in _post_clean
    self.validate_unique()
  File "/usr/local/lib/python2.7/dist-packages/django/forms/models.py", line 411, in validate_unique
    self.instance.validate_unique(exclude=exclude)
  File "/usr/local/lib/python2.7/dist-packages/django/db/models/base.py", line 922, in validate_unique
    errors = self._perform_unique_checks(unique_checks)
  File "/usr/local/lib/python2.7/dist-packages/django/db/models/base.py", line 1017, in _perform_unique_checks
    if qs.exists():
  File "/usr/local/lib/python2.7/dist-packages/django/db/models/query.py", line 651, in exists
    return self.query.has_results(using=self.db)
  File "/usr/local/lib/python2.7/dist-packages/django/db/models/sql/query.py", line 501, in has_results
    return compiler.has_results()
  File "/usr/local/lib/python2.7/dist-packages/django/db/models/sql/compiler.py", line 819, in has_results
    return bool(self.execute_sql(SINGLE))
  File "/usr/local/lib/python2.7/dist-packages/django/db/models/sql/compiler.py", line 848, in execute_sql
    cursor.execute(sql, params)
  File "/usr/local/lib/python2.7/dist-packages/django/db/backends/utils.py", line 64, in execute
    return self.cursor.execute(sql, params)
  File "/usr/local/lib/python2.7/dist-packages/django/db/utils.py", line 95, in __exit__
    six.reraise(dj_exc_type, dj_exc_value, traceback)
  File "/usr/local/lib/python2.7/dist-packages/django/db/backends/utils.py", line 64, in execute
    return self.cursor.execute(sql, params)
ProgrammingError: relation "base_user" does not exist
LINE 1: SELECT (1) AS "a" FROM "base_user" WHERE "base_user"."email"...
                               ^

ERROR 2016-03-23 15:22:42,086 base 17320 140127728568128 Internal Server Error: /newsite
Traceback (most recent call last):
  File "/usr/local/lib/python2.7/dist-packages/django/core/handlers/base.py", line 149, in get_response
    response = self.process_exception_by_middleware(e, request)
  File "/usr/local/lib/python2.7/dist-packages/django/core/handlers/base.py", line 147, in get_response
    response = wrapped_callback(request, *callback_args, **callback_kwargs)
  File "/opt/nbproject/apps/pages/views.py", line 172, in newsite
    if user_form.is_valid() and ensemble_form.is_valid():
  File "/usr/local/lib/python2.7/dist-packages/django/forms/forms.py", line 161, in is_valid
    return self.is_bound and not self.errors
  File "/usr/local/lib/python2.7/dist-packages/django/forms/forms.py", line 153, in errors
    self.full_clean()
  File "/usr/local/lib/python2.7/dist-packages/django/forms/forms.py", line 364, in full_clean
    self._post_clean()
  File "/usr/local/lib/python2.7/dist-packages/django/forms/models.py", line 402, in _post_clean
    self.validate_unique()
  File "/usr/local/lib/python2.7/dist-packages/django/forms/models.py", line 411, in validate_unique
    self.instance.validate_unique(exclude=exclude)
  File "/usr/local/lib/python2.7/dist-packages/django/db/models/base.py", line 922, in validate_unique
    errors = self._perform_unique_checks(unique_checks)
  File "/usr/local/lib/python2.7/dist-packages/django/db/models/base.py", line 1017, in _perform_unique_checks
    if qs.exists():
  File "/usr/local/lib/python2.7/dist-packages/django/db/models/query.py", line 651, in exists
    return self.query.has_results(using=self.db)
  File "/usr/local/lib/python2.7/dist-packages/django/db/models/sql/query.py", line 501, in has_results
    return compiler.has_results()
  File "/usr/local/lib/python2.7/dist-packages/django/db/models/sql/compiler.py", line 819, in has_results
    return bool(self.execute_sql(SINGLE))
  File "/usr/local/lib/python2.7/dist-packages/django/db/models/sql/compiler.py", line 848, in execute_sql
    cursor.execute(sql, params)
  File "/usr/local/lib/python2.7/dist-packages/django/db/backends/utils.py", line 64, in execute
    return self.cursor.execute(sql, params)
  File "/usr/local/lib/python2.7/dist-packages/django/db/utils.py", line 95, in __exit__
    six.reraise(dj_exc_type, dj_exc_value, traceback)
  File "/usr/local/lib/python2.7/dist-packages/django/db/backends/utils.py", line 64, in execute
    return self.cursor.execute(sql, params)
ProgrammingError: relation "base_user" does not exist
LINE 1: SELECT (1) AS "a" FROM "base_user" WHERE "base_user"."email"...
                               ^

ERROR 2016-03-23 15:43:19,359 base 17496 140476595500864 Internal Server Error: /newsite
Traceback (most recent call last):
  File "/usr/local/lib/python2.7/dist-packages/django/core/handlers/base.py", line 149, in get_response
    response = self.process_exception_by_middleware(e, request)
  File "/usr/local/lib/python2.7/dist-packages/django/core/handlers/base.py", line 147, in get_response
    response = wrapped_callback(request, *callback_args, **callback_kwargs)
  File "/opt/nbproject/apps/pages/views.py", line 172, in newsite
    if user_form.is_valid() and ensemble_form.is_valid():
  File "/usr/local/lib/python2.7/dist-packages/django/forms/forms.py", line 161, in is_valid
    return self.is_bound and not self.errors
  File "/usr/local/lib/python2.7/dist-packages/django/forms/forms.py", line 153, in errors
    self.full_clean()
  File "/usr/local/lib/python2.7/dist-packages/django/forms/forms.py", line 364, in full_clean
    self._post_clean()
  File "/usr/local/lib/python2.7/dist-packages/django/forms/models.py", line 402, in _post_clean
    self.validate_unique()
  File "/usr/local/lib/python2.7/dist-packages/django/forms/models.py", line 411, in validate_unique
    self.instance.validate_unique(exclude=exclude)
  File "/usr/local/lib/python2.7/dist-packages/django/db/models/base.py", line 922, in validate_unique
    errors = self._perform_unique_checks(unique_checks)
  File "/usr/local/lib/python2.7/dist-packages/django/db/models/base.py", line 1017, in _perform_unique_checks
    if qs.exists():
  File "/usr/local/lib/python2.7/dist-packages/django/db/models/query.py", line 651, in exists
    return self.query.has_results(using=self.db)
  File "/usr/local/lib/python2.7/dist-packages/django/db/models/sql/query.py", line 501, in has_results
    return compiler.has_results()
  File "/usr/local/lib/python2.7/dist-packages/django/db/models/sql/compiler.py", line 819, in has_results
    return bool(self.execute_sql(SINGLE))
  File "/usr/local/lib/python2.7/dist-packages/django/db/models/sql/compiler.py", line 848, in execute_sql
    cursor.execute(sql, params)
  File "/usr/local/lib/python2.7/dist-packages/django/db/backends/utils.py", line 64, in execute
    return self.cursor.execute(sql, params)
  File "/usr/local/lib/python2.7/dist-packages/django/db/utils.py", line 95, in __exit__
    six.reraise(dj_exc_type, dj_exc_value, traceback)
  File "/usr/local/lib/python2.7/dist-packages/django/db/backends/utils.py", line 64, in execute
    return self.cursor.execute(sql, params)
ProgrammingError: relation "base_user" does not exist
LINE 1: SELECT (1) AS "a" FROM "base_user" WHERE "base_user"."email"...
                               ^

ERROR 2016-03-23 15:43:24,408 base 17496 140476595500864 Internal Server Error: /newsite
Traceback (most recent call last):
  File "/usr/local/lib/python2.7/dist-packages/django/core/handlers/base.py", line 149, in get_response
    response = self.process_exception_by_middleware(e, request)
  File "/usr/local/lib/python2.7/dist-packages/django/core/handlers/base.py", line 147, in get_response
    response = wrapped_callback(request, *callback_args, **callback_kwargs)
  File "/opt/nbproject/apps/pages/views.py", line 172, in newsite
    if user_form.is_valid() and ensemble_form.is_valid():
  File "/usr/local/lib/python2.7/dist-packages/django/forms/forms.py", line 161, in is_valid
    return self.is_bound and not self.errors
  File "/usr/local/lib/python2.7/dist-packages/django/forms/forms.py", line 153, in errors
    self.full_clean()
  File "/usr/local/lib/python2.7/dist-packages/django/forms/forms.py", line 364, in full_clean
    self._post_clean()
  File "/usr/local/lib/python2.7/dist-packages/django/forms/models.py", line 402, in _post_clean
    self.validate_unique()
  File "/usr/local/lib/python2.7/dist-packages/django/forms/models.py", line 411, in validate_unique
    self.instance.validate_unique(exclude=exclude)
  File "/usr/local/lib/python2.7/dist-packages/django/db/models/base.py", line 922, in validate_unique
    errors = self._perform_unique_checks(unique_checks)
  File "/usr/local/lib/python2.7/dist-packages/django/db/models/base.py", line 1017, in _perform_unique_checks
    if qs.exists():
  File "/usr/local/lib/python2.7/dist-packages/django/db/models/query.py", line 651, in exists
    return self.query.has_results(using=self.db)
  File "/usr/local/lib/python2.7/dist-packages/django/db/models/sql/query.py", line 501, in has_results
    return compiler.has_results()
  File "/usr/local/lib/python2.7/dist-packages/django/db/models/sql/compiler.py", line 819, in has_results
    return bool(self.execute_sql(SINGLE))
  File "/usr/local/lib/python2.7/dist-packages/django/db/models/sql/compiler.py", line 848, in execute_sql
    cursor.execute(sql, params)
  File "/usr/local/lib/python2.7/dist-packages/django/db/backends/utils.py", line 64, in execute
    return self.cursor.execute(sql, params)
  File "/usr/local/lib/python2.7/dist-packages/django/db/utils.py", line 95, in __exit__
    six.reraise(dj_exc_type, dj_exc_value, traceback)
  File "/usr/local/lib/python2.7/dist-packages/django/db/backends/utils.py", line 64, in execute
    return self.cursor.execute(sql, params)
ProgrammingError: relation "base_user" does not exist
LINE 1: SELECT (1) AS "a" FROM "base_user" WHERE "base_user"."email"...
                               ^

ERROR 2016-03-23 15:45:13,505 base 17760 140063034324736 Internal Server Error: /newsite
Traceback (most recent call last):
  File "/usr/local/lib/python2.7/dist-packages/django/core/handlers/base.py", line 149, in get_response
    response = self.process_exception_by_middleware(e, request)
  File "/usr/local/lib/python2.7/dist-packages/django/core/handlers/base.py", line 147, in get_response
    response = wrapped_callback(request, *callback_args, **callback_kwargs)
  File "/opt/nbproject/apps/pages/views.py", line 172, in newsite
    if user_form.is_valid() and ensemble_form.is_valid():
  File "/usr/local/lib/python2.7/dist-packages/django/forms/forms.py", line 161, in is_valid
    return self.is_bound and not self.errors
  File "/usr/local/lib/python2.7/dist-packages/django/forms/forms.py", line 153, in errors
    self.full_clean()
  File "/usr/local/lib/python2.7/dist-packages/django/forms/forms.py", line 364, in full_clean
    self._post_clean()
  File "/usr/local/lib/python2.7/dist-packages/django/forms/models.py", line 402, in _post_clean
    self.validate_unique()
  File "/usr/local/lib/python2.7/dist-packages/django/forms/models.py", line 411, in validate_unique
    self.instance.validate_unique(exclude=exclude)
  File "/usr/local/lib/python2.7/dist-packages/django/db/models/base.py", line 922, in validate_unique
    errors = self._perform_unique_checks(unique_checks)
  File "/usr/local/lib/python2.7/dist-packages/django/db/models/base.py", line 1017, in _perform_unique_checks
    if qs.exists():
  File "/usr/local/lib/python2.7/dist-packages/django/db/models/query.py", line 651, in exists
    return self.query.has_results(using=self.db)
  File "/usr/local/lib/python2.7/dist-packages/django/db/models/sql/query.py", line 501, in has_results
    return compiler.has_results()
  File "/usr/local/lib/python2.7/dist-packages/django/db/models/sql/compiler.py", line 819, in has_results
    return bool(self.execute_sql(SINGLE))
  File "/usr/local/lib/python2.7/dist-packages/django/db/models/sql/compiler.py", line 848, in execute_sql
    cursor.execute(sql, params)
  File "/usr/local/lib/python2.7/dist-packages/django/db/backends/utils.py", line 64, in execute
    return self.cursor.execute(sql, params)
  File "/usr/local/lib/python2.7/dist-packages/django/db/utils.py", line 95, in __exit__
    six.reraise(dj_exc_type, dj_exc_value, traceback)
  File "/usr/local/lib/python2.7/dist-packages/django/db/backends/utils.py", line 64, in execute
    return self.cursor.execute(sql, params)
ProgrammingError: relation "base_user" does not exist
LINE 1: SELECT (1) AS "a" FROM "base_user" WHERE "base_user"."email"...
                               ^

ERROR 2016-03-29 16:47:03,479 base 8787 140161659221824 Internal Server Error: /newsite
Traceback (most recent call last):
  File "/usr/local/lib/python2.7/dist-packages/django/core/handlers/base.py", line 149, in get_response
    response = self.process_exception_by_middleware(e, request)
  File "/usr/local/lib/python2.7/dist-packages/django/core/handlers/base.py", line 147, in get_response
    response = wrapped_callback(request, *callback_args, **callback_kwargs)
  File "/opt/nbproject/apps/pages/views.py", line 190, in newsite
    email.send()
  File "/usr/local/lib/python2.7/dist-packages/django/core/mail/message.py", line 292, in send
    return self.get_connection(fail_silently).send_messages([self])
  File "/usr/local/lib/python2.7/dist-packages/django/core/mail/backends/smtp.py", line 100, in send_messages
    new_conn_created = self.open()
  File "/usr/local/lib/python2.7/dist-packages/django/core/mail/backends/smtp.py", line 58, in open
    self.connection = connection_class(self.host, self.port, **connection_params)
  File "/usr/lib/python2.7/smtplib.py", line 256, in __init__
    (code, msg) = self.connect(host, port)
  File "/usr/lib/python2.7/smtplib.py", line 316, in connect
    self.sock = self._get_socket(host, port, self.timeout)
  File "/usr/lib/python2.7/smtplib.py", line 291, in _get_socket
    return socket.create_connection((host, port), timeout)
  File "/usr/lib/python2.7/socket.py", line 575, in create_connection
    raise err
error: [Errno 111] Connection refused
ERROR 2016-03-30 09:22:55,087 base 21938 140005505967936 Internal Server Error: /newsite
Traceback (most recent call last):
  File "/usr/local/lib/python2.7/dist-packages/django/core/handlers/base.py", line 149, in get_response
    response = self.process_exception_by_middleware(e, request)
  File "/usr/local/lib/python2.7/dist-packages/django/core/handlers/base.py", line 147, in get_response
    response = wrapped_callback(request, *callback_args, **callback_kwargs)
  File "/opt/nbproject/apps/pages/views.py", line 190, in newsite
    email.send()
  File "/usr/local/lib/python2.7/dist-packages/django/core/mail/message.py", line 292, in send
    return self.get_connection(fail_silently).send_messages([self])
  File "/usr/local/lib/python2.7/dist-packages/django/core/mail/backends/smtp.py", line 100, in send_messages
    new_conn_created = self.open()
  File "/usr/local/lib/python2.7/dist-packages/django/core/mail/backends/smtp.py", line 58, in open
    self.connection = connection_class(self.host, self.port, **connection_params)
  File "/usr/lib/python2.7/smtplib.py", line 256, in __init__
    (code, msg) = self.connect(host, port)
  File "/usr/lib/python2.7/smtplib.py", line 316, in connect
    self.sock = self._get_socket(host, port, self.timeout)
  File "/usr/lib/python2.7/smtplib.py", line 291, in _get_socket
    return socket.create_connection((host, port), timeout)
  File "/usr/lib/python2.7/socket.py", line 575, in create_connection
    raise err
error: [Errno 111] Connection refused
ERROR 2016-03-30 09:58:23,321 base 22119 140697782929216 Internal Server Error: /pdf4/rpc
Traceback (most recent call last):
  File "/usr/local/lib/python2.7/dist-packages/django/core/handlers/base.py", line 149, in get_response
    response = self.process_exception_by_middleware(e, request)
  File "/usr/local/lib/python2.7/dist-packages/django/core/handlers/base.py", line 147, in get_response
    response = wrapped_callback(request, *callback_args, **callback_kwargs)
  File "/usr/local/lib/python2.7/dist-packages/django/views/decorators/csrf.py", line 58, in wrapped_view
    return view_func(*args, **kwargs)
  File "/opt/nbproject/apps/rpc/views.py", line 808, in run
    r.content = getattr(MODULE, fctname)(payload, req)
  File "/opt/nbproject/apps/rpc/views.py", line 310, in getObjects
    output[t] = getattr(annotations, "get_"+t)(uid, p2)
  File "/opt/nbproject/apps/base/annotations.py", line 275, in get_file_stats
    return  db.Db().getIndexedObjects(names, "id", from_clause, "true" , (uid,uid, uid, uid, id_ensemble))
  File "/opt/nbproject/apps/base/db.py", line 127, in getIndexedObjects
    c = self.execute(qry, args, connection)
  File "/opt/nbproject/apps/base/db.py", line 49, in execute
    cursor.execute(qry, args)
  File "/usr/local/lib/python2.7/dist-packages/django/db/backends/utils.py", line 64, in execute
    return self.cursor.execute(sql, params)
  File "/usr/local/lib/python2.7/dist-packages/django/db/utils.py", line 95, in __exit__
    six.reraise(dj_exc_type, dj_exc_value, traceback)
  File "/usr/local/lib/python2.7/dist-packages/django/db/backends/utils.py", line 64, in execute
    return self.cursor.execute(sql, params)
ProgrammingError: relation "base_v_comment" does not exist
LINE 2: from base_v_comment vc left join (select distinct comment_id...
             ^

ERROR 2016-03-30 10:04:55,883 base 22119 140697782929216 Internal Server Error: /pdf4/rpc
Traceback (most recent call last):
  File "/usr/local/lib/python2.7/dist-packages/django/core/handlers/base.py", line 149, in get_response
    response = self.process_exception_by_middleware(e, request)
  File "/usr/local/lib/python2.7/dist-packages/django/core/handlers/base.py", line 147, in get_response
    response = wrapped_callback(request, *callback_args, **callback_kwargs)
  File "/usr/local/lib/python2.7/dist-packages/django/views/decorators/csrf.py", line 58, in wrapped_view
    return view_func(*args, **kwargs)
  File "/opt/nbproject/apps/rpc/views.py", line 808, in run
    r.content = getattr(MODULE, fctname)(payload, req)
  File "/opt/nbproject/apps/rpc/views.py", line 310, in getObjects
    output[t] = getattr(annotations, "get_"+t)(uid, p2)
  File "/opt/nbproject/apps/base/annotations.py", line 275, in get_file_stats
    return  db.Db().getIndexedObjects(names, "id", from_clause, "true" , (uid,uid, uid, uid, id_ensemble))
  File "/opt/nbproject/apps/base/db.py", line 127, in getIndexedObjects
    c = self.execute(qry, args, connection)
  File "/opt/nbproject/apps/base/db.py", line 49, in execute
    cursor.execute(qry, args)
  File "/usr/local/lib/python2.7/dist-packages/django/db/backends/utils.py", line 64, in execute
    return self.cursor.execute(sql, params)
  File "/usr/local/lib/python2.7/dist-packages/django/db/utils.py", line 95, in __exit__
    six.reraise(dj_exc_type, dj_exc_value, traceback)
  File "/usr/local/lib/python2.7/dist-packages/django/db/backends/utils.py", line 64, in execute
    return self.cursor.execute(sql, params)
ProgrammingError: relation "base_v_comment" does not exist
LINE 2: from base_v_comment vc left join (select distinct comment_id...
             ^

ERROR 2016-04-04 09:55:36,569 base 22119 140697782929216 Internal Server Error: /pdf4/rpc
Traceback (most recent call last):
  File "/usr/local/lib/python2.7/dist-packages/django/core/handlers/base.py", line 149, in get_response
    response = self.process_exception_by_middleware(e, request)
  File "/usr/local/lib/python2.7/dist-packages/django/core/handlers/base.py", line 147, in get_response
    response = wrapped_callback(request, *callback_args, **callback_kwargs)
  File "/usr/local/lib/python2.7/dist-packages/django/views/decorators/csrf.py", line 58, in wrapped_view
    return view_func(*args, **kwargs)
  File "/opt/nbproject/apps/rpc/views.py", line 808, in run
    r.content = getattr(MODULE, fctname)(payload, req)
  File "/opt/nbproject/apps/rpc/views.py", line 310, in getObjects
    output[t] = getattr(annotations, "get_"+t)(uid, p2)
  File "/opt/nbproject/apps/base/annotations.py", line 275, in get_file_stats
    return  db.Db().getIndexedObjects(names, "id", from_clause, "true" , (uid,uid, uid, uid, id_ensemble))
  File "/opt/nbproject/apps/base/db.py", line 127, in getIndexedObjects
    c = self.execute(qry, args, connection)
  File "/opt/nbproject/apps/base/db.py", line 49, in execute
    cursor.execute(qry, args)
  File "/usr/local/lib/python2.7/dist-packages/django/db/backends/utils.py", line 64, in execute
    return self.cursor.execute(sql, params)
  File "/usr/local/lib/python2.7/dist-packages/django/db/utils.py", line 95, in __exit__
    six.reraise(dj_exc_type, dj_exc_value, traceback)
  File "/usr/local/lib/python2.7/dist-packages/django/db/backends/utils.py", line 64, in execute
    return self.cursor.execute(sql, params)
ProgrammingError: relation "base_v_comment" does not exist
LINE 2: from base_v_comment vc left join (select distinct comment_id...
             ^

ERROR 2016-04-04 09:56:14,261 base 22119 140697782929216 Internal Server Error: /pdf4/rpc
Traceback (most recent call last):
  File "/usr/local/lib/python2.7/dist-packages/django/core/handlers/base.py", line 149, in get_response
    response = self.process_exception_by_middleware(e, request)
  File "/usr/local/lib/python2.7/dist-packages/django/core/handlers/base.py", line 147, in get_response
    response = wrapped_callback(request, *callback_args, **callback_kwargs)
  File "/usr/local/lib/python2.7/dist-packages/django/views/decorators/csrf.py", line 58, in wrapped_view
    return view_func(*args, **kwargs)
  File "/opt/nbproject/apps/rpc/views.py", line 808, in run
    r.content = getattr(MODULE, fctname)(payload, req)
  File "/opt/nbproject/apps/rpc/views.py", line 310, in getObjects
    output[t] = getattr(annotations, "get_"+t)(uid, p2)
  File "/opt/nbproject/apps/base/annotations.py", line 275, in get_file_stats
    return  db.Db().getIndexedObjects(names, "id", from_clause, "true" , (uid,uid, uid, uid, id_ensemble))
  File "/opt/nbproject/apps/base/db.py", line 127, in getIndexedObjects
    c = self.execute(qry, args, connection)
  File "/opt/nbproject/apps/base/db.py", line 49, in execute
    cursor.execute(qry, args)
  File "/usr/local/lib/python2.7/dist-packages/django/db/backends/utils.py", line 64, in execute
    return self.cursor.execute(sql, params)
  File "/usr/local/lib/python2.7/dist-packages/django/db/utils.py", line 95, in __exit__
    six.reraise(dj_exc_type, dj_exc_value, traceback)
  File "/usr/local/lib/python2.7/dist-packages/django/db/backends/utils.py", line 64, in execute
    return self.cursor.execute(sql, params)
ProgrammingError: relation "base_v_comment" does not exist
LINE 2: from base_v_comment vc left join (select distinct comment_id...
             ^

ERROR 2016-04-04 11:30:14,684 base 22119 140697782929216 Internal Server Error: /pdf4/rpc
Traceback (most recent call last):
  File "/usr/local/lib/python2.7/dist-packages/django/core/handlers/base.py", line 149, in get_response
    response = self.process_exception_by_middleware(e, request)
  File "/usr/local/lib/python2.7/dist-packages/django/core/handlers/base.py", line 147, in get_response
    response = wrapped_callback(request, *callback_args, **callback_kwargs)
  File "/usr/local/lib/python2.7/dist-packages/django/views/decorators/csrf.py", line 58, in wrapped_view
    return view_func(*args, **kwargs)
  File "/opt/nbproject/apps/rpc/views.py", line 808, in run
    r.content = getattr(MODULE, fctname)(payload, req)
  File "/opt/nbproject/apps/rpc/views.py", line 310, in getObjects
    output[t] = getattr(annotations, "get_"+t)(uid, p2)
  File "/opt/nbproject/apps/base/annotations.py", line 275, in get_file_stats
    return  db.Db().getIndexedObjects(names, "id", from_clause, "true" , (uid,uid, uid, uid, id_ensemble))
  File "/opt/nbproject/apps/base/db.py", line 127, in getIndexedObjects
    c = self.execute(qry, args, connection)
  File "/opt/nbproject/apps/base/db.py", line 49, in execute
    cursor.execute(qry, args)
  File "/usr/local/lib/python2.7/dist-packages/django/db/backends/utils.py", line 64, in execute
    return self.cursor.execute(sql, params)
  File "/usr/local/lib/python2.7/dist-packages/django/db/utils.py", line 95, in __exit__
    six.reraise(dj_exc_type, dj_exc_value, traceback)
  File "/usr/local/lib/python2.7/dist-packages/django/db/backends/utils.py", line 64, in execute
    return self.cursor.execute(sql, params)
ProgrammingError: relation "base_v_comment" does not exist
LINE 2: from base_v_comment vc left join (select distinct comment_id...
             ^

ERROR 2016-04-07 15:22:14,177 base 24697 140716271146816 Internal Server Error: /pdf4/rpc
Traceback (most recent call last):
  File "/usr/local/lib/python2.7/dist-packages/django/core/handlers/base.py", line 149, in get_response
    response = self.process_exception_by_middleware(e, request)
  File "/usr/local/lib/python2.7/dist-packages/django/core/handlers/base.py", line 147, in get_response
    response = wrapped_callback(request, *callback_args, **callback_kwargs)
  File "/usr/local/lib/python2.7/dist-packages/django/views/decorators/csrf.py", line 58, in wrapped_view
    return view_func(*args, **kwargs)
  File "/opt/nbproject/apps/rpc/views.py", line 808, in run
    r.content = getattr(MODULE, fctname)(payload, req)
  File "/opt/nbproject/apps/rpc/views.py", line 310, in getObjects
    output[t] = getattr(annotations, "get_"+t)(uid, p2)
  File "/opt/nbproject/apps/base/annotations.py", line 275, in get_file_stats
    return  db.Db().getIndexedObjects(names, "id", from_clause, "true" , (uid,uid, uid, uid, id_ensemble))
  File "/opt/nbproject/apps/base/db.py", line 127, in getIndexedObjects
    c = self.execute(qry, args, connection)
  File "/opt/nbproject/apps/base/db.py", line 49, in execute
    cursor.execute(qry, args)
  File "/usr/local/lib/python2.7/dist-packages/django/db/backends/utils.py", line 64, in execute
    return self.cursor.execute(sql, params)
  File "/usr/local/lib/python2.7/dist-packages/django/db/utils.py", line 95, in __exit__
    six.reraise(dj_exc_type, dj_exc_value, traceback)
  File "/usr/local/lib/python2.7/dist-packages/django/db/backends/utils.py", line 64, in execute
    return self.cursor.execute(sql, params)
ProgrammingError: relation "base_v_comment" does not exist
LINE 2: from base_v_comment vc left join (select distinct comment_id...
             ^

ERROR 2016-04-07 15:23:03,959 base 24697 140716271146816 Internal Server Error: /pdf4/rpc
Traceback (most recent call last):
  File "/usr/local/lib/python2.7/dist-packages/django/core/handlers/base.py", line 149, in get_response
    response = self.process_exception_by_middleware(e, request)
  File "/usr/local/lib/python2.7/dist-packages/django/core/handlers/base.py", line 147, in get_response
    response = wrapped_callback(request, *callback_args, **callback_kwargs)
  File "/usr/local/lib/python2.7/dist-packages/django/views/decorators/csrf.py", line 58, in wrapped_view
    return view_func(*args, **kwargs)
  File "/opt/nbproject/apps/rpc/views.py", line 808, in run
    r.content = getattr(MODULE, fctname)(payload, req)
  File "/opt/nbproject/apps/rpc/views.py", line 310, in getObjects
    output[t] = getattr(annotations, "get_"+t)(uid, p2)
  File "/opt/nbproject/apps/base/annotations.py", line 275, in get_file_stats
    return  db.Db().getIndexedObjects(names, "id", from_clause, "true" , (uid,uid, uid, uid, id_ensemble))
  File "/opt/nbproject/apps/base/db.py", line 127, in getIndexedObjects
    c = self.execute(qry, args, connection)
  File "/opt/nbproject/apps/base/db.py", line 49, in execute
    cursor.execute(qry, args)
  File "/usr/local/lib/python2.7/dist-packages/django/db/backends/utils.py", line 64, in execute
    return self.cursor.execute(sql, params)
  File "/usr/local/lib/python2.7/dist-packages/django/db/utils.py", line 95, in __exit__
    six.reraise(dj_exc_type, dj_exc_value, traceback)
  File "/usr/local/lib/python2.7/dist-packages/django/db/backends/utils.py", line 64, in execute
    return self.cursor.execute(sql, params)
ProgrammingError: relation "base_v_comment" does not exist
LINE 2: from base_v_comment vc left join (select distinct comment_id...
             ^

ERROR 2016-04-07 15:23:05,590 base 24697 140716271146816 Internal Server Error: /pdf4/rpc
Traceback (most recent call last):
  File "/usr/local/lib/python2.7/dist-packages/django/core/handlers/base.py", line 149, in get_response
    response = self.process_exception_by_middleware(e, request)
  File "/usr/local/lib/python2.7/dist-packages/django/core/handlers/base.py", line 147, in get_response
    response = wrapped_callback(request, *callback_args, **callback_kwargs)
  File "/usr/local/lib/python2.7/dist-packages/django/views/decorators/csrf.py", line 58, in wrapped_view
    return view_func(*args, **kwargs)
  File "/opt/nbproject/apps/rpc/views.py", line 808, in run
    r.content = getattr(MODULE, fctname)(payload, req)
  File "/opt/nbproject/apps/rpc/views.py", line 310, in getObjects
    output[t] = getattr(annotations, "get_"+t)(uid, p2)
  File "/opt/nbproject/apps/base/annotations.py", line 275, in get_file_stats
    return  db.Db().getIndexedObjects(names, "id", from_clause, "true" , (uid,uid, uid, uid, id_ensemble))
  File "/opt/nbproject/apps/base/db.py", line 127, in getIndexedObjects
    c = self.execute(qry, args, connection)
  File "/opt/nbproject/apps/base/db.py", line 49, in execute
    cursor.execute(qry, args)
  File "/usr/local/lib/python2.7/dist-packages/django/db/backends/utils.py", line 64, in execute
    return self.cursor.execute(sql, params)
  File "/usr/local/lib/python2.7/dist-packages/django/db/utils.py", line 95, in __exit__
    six.reraise(dj_exc_type, dj_exc_value, traceback)
  File "/usr/local/lib/python2.7/dist-packages/django/db/backends/utils.py", line 64, in execute
    return self.cursor.execute(sql, params)
ProgrammingError: relation "base_v_comment" does not exist
LINE 2: from base_v_comment vc left join (select distinct comment_id...
             ^

ERROR 2016-04-07 15:23:54,341 base 24697 140716271146816 Internal Server Error: /addyoutube/4
Traceback (most recent call last):
  File "/usr/local/lib/python2.7/dist-packages/django/core/handlers/base.py", line 149, in get_response
    response = self.process_exception_by_middleware(e, request)
  File "/usr/local/lib/python2.7/dist-packages/django/core/handlers/base.py", line 147, in get_response
    response = wrapped_callback(request, *callback_args, **callback_kwargs)
  File "/opt/nbproject/apps/pages/views.py", line 292, in add_youtube_doc
    ginfo = youtube.videos().list(part="id,contentDetails,snippet", id=key).execute()
  File "/usr/local/lib/python2.7/dist-packages/oauth2client/util.py", line 137, in positional_wrapper
    return wrapped(*args, **kwargs)
  File "/usr/local/lib/python2.7/dist-packages/googleapiclient/http.py", line 760, in execute
    raise HttpError(resp, content, uri=self.uri)
HttpError: <HttpError 400 when requesting https://www.googleapis.com/youtube/v3/videos?alt=json&part=id%2CcontentDetails%2Csnippet&id=gQuZH3ROoGM&key=CHANGE_ME returned "Bad Request">
ERROR 2016-04-07 15:24:35,083 base 24697 140716271146816 Internal Server Error: /pdf4/rpc
Traceback (most recent call last):
  File "/usr/local/lib/python2.7/dist-packages/django/core/handlers/base.py", line 149, in get_response
    response = self.process_exception_by_middleware(e, request)
  File "/usr/local/lib/python2.7/dist-packages/django/core/handlers/base.py", line 147, in get_response
    response = wrapped_callback(request, *callback_args, **callback_kwargs)
  File "/usr/local/lib/python2.7/dist-packages/django/views/decorators/csrf.py", line 58, in wrapped_view
    return view_func(*args, **kwargs)
  File "/opt/nbproject/apps/rpc/views.py", line 808, in run
    r.content = getattr(MODULE, fctname)(payload, req)
  File "/opt/nbproject/apps/rpc/views.py", line 310, in getObjects
    output[t] = getattr(annotations, "get_"+t)(uid, p2)
  File "/opt/nbproject/apps/base/annotations.py", line 275, in get_file_stats
    return  db.Db().getIndexedObjects(names, "id", from_clause, "true" , (uid,uid, uid, uid, id_ensemble))
  File "/opt/nbproject/apps/base/db.py", line 127, in getIndexedObjects
    c = self.execute(qry, args, connection)
  File "/opt/nbproject/apps/base/db.py", line 49, in execute
    cursor.execute(qry, args)
  File "/usr/local/lib/python2.7/dist-packages/django/db/backends/utils.py", line 64, in execute
    return self.cursor.execute(sql, params)
  File "/usr/local/lib/python2.7/dist-packages/django/db/utils.py", line 95, in __exit__
    six.reraise(dj_exc_type, dj_exc_value, traceback)
  File "/usr/local/lib/python2.7/dist-packages/django/db/backends/utils.py", line 64, in execute
    return self.cursor.execute(sql, params)
ProgrammingError: relation "base_v_comment" does not exist
LINE 2: from base_v_comment vc left join (select distinct comment_id...
             ^

ERROR 2016-04-07 15:28:14,484 base 24697 140716271146816 Internal Server Error: /pdf4/rpc
Traceback (most recent call last):
  File "/usr/local/lib/python2.7/dist-packages/django/core/handlers/base.py", line 149, in get_response
    response = self.process_exception_by_middleware(e, request)
  File "/usr/local/lib/python2.7/dist-packages/django/core/handlers/base.py", line 147, in get_response
    response = wrapped_callback(request, *callback_args, **callback_kwargs)
  File "/usr/local/lib/python2.7/dist-packages/django/views/decorators/csrf.py", line 58, in wrapped_view
    return view_func(*args, **kwargs)
  File "/opt/nbproject/apps/rpc/views.py", line 808, in run
    r.content = getattr(MODULE, fctname)(payload, req)
  File "/opt/nbproject/apps/rpc/views.py", line 310, in getObjects
    output[t] = getattr(annotations, "get_"+t)(uid, p2)
  File "/opt/nbproject/apps/base/annotations.py", line 275, in get_file_stats
    return  db.Db().getIndexedObjects(names, "id", from_clause, "true" , (uid,uid, uid, uid, id_ensemble))
  File "/opt/nbproject/apps/base/db.py", line 127, in getIndexedObjects
    c = self.execute(qry, args, connection)
  File "/opt/nbproject/apps/base/db.py", line 49, in execute
    cursor.execute(qry, args)
  File "/usr/local/lib/python2.7/dist-packages/django/db/backends/utils.py", line 64, in execute
    return self.cursor.execute(sql, params)
  File "/usr/local/lib/python2.7/dist-packages/django/db/utils.py", line 95, in __exit__
    six.reraise(dj_exc_type, dj_exc_value, traceback)
  File "/usr/local/lib/python2.7/dist-packages/django/db/backends/utils.py", line 64, in execute
    return self.cursor.execute(sql, params)
ProgrammingError: relation "base_v_comment" does not exist
LINE 2: from base_v_comment vc left join (select distinct comment_id...
             ^

ERROR 2016-04-07 15:29:00,390 base 24697 140716271146816 Internal Server Error: /pdf4/rpc
Traceback (most recent call last):
  File "/usr/local/lib/python2.7/dist-packages/django/core/handlers/base.py", line 149, in get_response
    response = self.process_exception_by_middleware(e, request)
  File "/usr/local/lib/python2.7/dist-packages/django/core/handlers/base.py", line 147, in get_response
    response = wrapped_callback(request, *callback_args, **callback_kwargs)
  File "/usr/local/lib/python2.7/dist-packages/django/views/decorators/csrf.py", line 58, in wrapped_view
    return view_func(*args, **kwargs)
  File "/opt/nbproject/apps/rpc/views.py", line 808, in run
    r.content = getattr(MODULE, fctname)(payload, req)
  File "/opt/nbproject/apps/rpc/views.py", line 310, in getObjects
    output[t] = getattr(annotations, "get_"+t)(uid, p2)
  File "/opt/nbproject/apps/base/annotations.py", line 275, in get_file_stats
    return  db.Db().getIndexedObjects(names, "id", from_clause, "true" , (uid,uid, uid, uid, id_ensemble))
  File "/opt/nbproject/apps/base/db.py", line 127, in getIndexedObjects
    c = self.execute(qry, args, connection)
  File "/opt/nbproject/apps/base/db.py", line 49, in execute
    cursor.execute(qry, args)
  File "/usr/local/lib/python2.7/dist-packages/django/db/backends/utils.py", line 64, in execute
    return self.cursor.execute(sql, params)
  File "/usr/local/lib/python2.7/dist-packages/django/db/utils.py", line 95, in __exit__
    six.reraise(dj_exc_type, dj_exc_value, traceback)
  File "/usr/local/lib/python2.7/dist-packages/django/db/backends/utils.py", line 64, in execute
    return self.cursor.execute(sql, params)
ProgrammingError: relation "base_v_comment" does not exist
LINE 2: from base_v_comment vc left join (select distinct comment_id...
             ^

ERROR 2016-04-07 15:29:02,989 base 24697 140716271146816 Internal Server Error: /pdf4/rpc
Traceback (most recent call last):
  File "/usr/local/lib/python2.7/dist-packages/django/core/handlers/base.py", line 149, in get_response
    response = self.process_exception_by_middleware(e, request)
  File "/usr/local/lib/python2.7/dist-packages/django/core/handlers/base.py", line 147, in get_response
    response = wrapped_callback(request, *callback_args, **callback_kwargs)
  File "/usr/local/lib/python2.7/dist-packages/django/views/decorators/csrf.py", line 58, in wrapped_view
    return view_func(*args, **kwargs)
  File "/opt/nbproject/apps/rpc/views.py", line 808, in run
    r.content = getattr(MODULE, fctname)(payload, req)
  File "/opt/nbproject/apps/rpc/views.py", line 310, in getObjects
    output[t] = getattr(annotations, "get_"+t)(uid, p2)
  File "/opt/nbproject/apps/base/annotations.py", line 275, in get_file_stats
    return  db.Db().getIndexedObjects(names, "id", from_clause, "true" , (uid,uid, uid, uid, id_ensemble))
  File "/opt/nbproject/apps/base/db.py", line 127, in getIndexedObjects
    c = self.execute(qry, args, connection)
  File "/opt/nbproject/apps/base/db.py", line 49, in execute
    cursor.execute(qry, args)
  File "/usr/local/lib/python2.7/dist-packages/django/db/backends/utils.py", line 64, in execute
    return self.cursor.execute(sql, params)
  File "/usr/local/lib/python2.7/dist-packages/django/db/utils.py", line 95, in __exit__
    six.reraise(dj_exc_type, dj_exc_value, traceback)
  File "/usr/local/lib/python2.7/dist-packages/django/db/backends/utils.py", line 64, in execute
    return self.cursor.execute(sql, params)
ProgrammingError: relation "base_v_comment" does not exist
LINE 2: from base_v_comment vc left join (select distinct comment_id...
             ^

ERROR 2016-04-08 10:17:35,127 base 24697 140716271146816 Internal Server Error: /pdf4/rpc
Traceback (most recent call last):
  File "/usr/local/lib/python2.7/dist-packages/django/core/handlers/base.py", line 149, in get_response
    response = self.process_exception_by_middleware(e, request)
  File "/usr/local/lib/python2.7/dist-packages/django/core/handlers/base.py", line 147, in get_response
    response = wrapped_callback(request, *callback_args, **callback_kwargs)
  File "/usr/local/lib/python2.7/dist-packages/django/views/decorators/csrf.py", line 58, in wrapped_view
    return view_func(*args, **kwargs)
  File "/opt/nbproject/apps/rpc/views.py", line 808, in run
    r.content = getattr(MODULE, fctname)(payload, req)
  File "/opt/nbproject/apps/rpc/views.py", line 310, in getObjects
    output[t] = getattr(annotations, "get_"+t)(uid, p2)
  File "/opt/nbproject/apps/base/annotations.py", line 275, in get_file_stats
    return  db.Db().getIndexedObjects(names, "id", from_clause, "true" , (uid,uid, uid, uid, id_ensemble))
  File "/opt/nbproject/apps/base/db.py", line 127, in getIndexedObjects
    c = self.execute(qry, args, connection)
  File "/opt/nbproject/apps/base/db.py", line 49, in execute
    cursor.execute(qry, args)
  File "/usr/local/lib/python2.7/dist-packages/django/db/backends/utils.py", line 64, in execute
    return self.cursor.execute(sql, params)
  File "/usr/local/lib/python2.7/dist-packages/django/db/utils.py", line 95, in __exit__
    six.reraise(dj_exc_type, dj_exc_value, traceback)
  File "/usr/local/lib/python2.7/dist-packages/django/db/backends/utils.py", line 64, in execute
    return self.cursor.execute(sql, params)
ProgrammingError: relation "base_v_comment" does not exist
LINE 2: from base_v_comment vc left join (select distinct comment_id...
             ^

ERROR 2016-04-08 10:26:30,288 base 24697 140716271146816 Internal Server Error: /pdf4/rpc
Traceback (most recent call last):
  File "/usr/local/lib/python2.7/dist-packages/django/core/handlers/base.py", line 149, in get_response
    response = self.process_exception_by_middleware(e, request)
  File "/usr/local/lib/python2.7/dist-packages/django/core/handlers/base.py", line 147, in get_response
    response = wrapped_callback(request, *callback_args, **callback_kwargs)
  File "/usr/local/lib/python2.7/dist-packages/django/views/decorators/csrf.py", line 58, in wrapped_view
    return view_func(*args, **kwargs)
  File "/opt/nbproject/apps/rpc/views.py", line 808, in run
    r.content = getattr(MODULE, fctname)(payload, req)
  File "/opt/nbproject/apps/rpc/views.py", line 310, in getObjects
    output[t] = getattr(annotations, "get_"+t)(uid, p2)
  File "/opt/nbproject/apps/base/annotations.py", line 275, in get_file_stats
    return  db.Db().getIndexedObjects(names, "id", from_clause, "true" , (uid,uid, uid, uid, id_ensemble))
  File "/opt/nbproject/apps/base/db.py", line 127, in getIndexedObjects
    c = self.execute(qry, args, connection)
  File "/opt/nbproject/apps/base/db.py", line 49, in execute
    cursor.execute(qry, args)
  File "/usr/local/lib/python2.7/dist-packages/django/db/backends/utils.py", line 64, in execute
    return self.cursor.execute(sql, params)
  File "/usr/local/lib/python2.7/dist-packages/django/db/utils.py", line 95, in __exit__
    six.reraise(dj_exc_type, dj_exc_value, traceback)
  File "/usr/local/lib/python2.7/dist-packages/django/db/backends/utils.py", line 64, in execute
    return self.cursor.execute(sql, params)
ProgrammingError: relation "base_v_comment" does not exist
LINE 2: from base_v_comment vc left join (select distinct comment_id...
             ^

ERROR 2016-04-08 10:26:31,238 base 24697 140716271146816 Internal Server Error: /pdf4/rpc
Traceback (most recent call last):
  File "/usr/local/lib/python2.7/dist-packages/django/core/handlers/base.py", line 149, in get_response
    response = self.process_exception_by_middleware(e, request)
  File "/usr/local/lib/python2.7/dist-packages/django/core/handlers/base.py", line 147, in get_response
    response = wrapped_callback(request, *callback_args, **callback_kwargs)
  File "/usr/local/lib/python2.7/dist-packages/django/views/decorators/csrf.py", line 58, in wrapped_view
    return view_func(*args, **kwargs)
  File "/opt/nbproject/apps/rpc/views.py", line 808, in run
    r.content = getattr(MODULE, fctname)(payload, req)
  File "/opt/nbproject/apps/rpc/views.py", line 310, in getObjects
    output[t] = getattr(annotations, "get_"+t)(uid, p2)
  File "/opt/nbproject/apps/base/annotations.py", line 275, in get_file_stats
    return  db.Db().getIndexedObjects(names, "id", from_clause, "true" , (uid,uid, uid, uid, id_ensemble))
  File "/opt/nbproject/apps/base/db.py", line 127, in getIndexedObjects
    c = self.execute(qry, args, connection)
  File "/opt/nbproject/apps/base/db.py", line 49, in execute
    cursor.execute(qry, args)
  File "/usr/local/lib/python2.7/dist-packages/django/db/backends/utils.py", line 64, in execute
    return self.cursor.execute(sql, params)
  File "/usr/local/lib/python2.7/dist-packages/django/db/utils.py", line 95, in __exit__
    six.reraise(dj_exc_type, dj_exc_value, traceback)
  File "/usr/local/lib/python2.7/dist-packages/django/db/backends/utils.py", line 64, in execute
    return self.cursor.execute(sql, params)
ProgrammingError: relation "base_v_comment" does not exist
LINE 2: from base_v_comment vc left join (select distinct comment_id...
             ^

ERROR 2016-04-08 10:26:32,081 base 24697 140716271146816 Internal Server Error: /pdf4/rpc
Traceback (most recent call last):
  File "/usr/local/lib/python2.7/dist-packages/django/core/handlers/base.py", line 149, in get_response
    response = self.process_exception_by_middleware(e, request)
  File "/usr/local/lib/python2.7/dist-packages/django/core/handlers/base.py", line 147, in get_response
    response = wrapped_callback(request, *callback_args, **callback_kwargs)
  File "/usr/local/lib/python2.7/dist-packages/django/views/decorators/csrf.py", line 58, in wrapped_view
    return view_func(*args, **kwargs)
  File "/opt/nbproject/apps/rpc/views.py", line 808, in run
    r.content = getattr(MODULE, fctname)(payload, req)
  File "/opt/nbproject/apps/rpc/views.py", line 310, in getObjects
    output[t] = getattr(annotations, "get_"+t)(uid, p2)
  File "/opt/nbproject/apps/base/annotations.py", line 275, in get_file_stats
    return  db.Db().getIndexedObjects(names, "id", from_clause, "true" , (uid,uid, uid, uid, id_ensemble))
  File "/opt/nbproject/apps/base/db.py", line 127, in getIndexedObjects
    c = self.execute(qry, args, connection)
  File "/opt/nbproject/apps/base/db.py", line 49, in execute
    cursor.execute(qry, args)
  File "/usr/local/lib/python2.7/dist-packages/django/db/backends/utils.py", line 64, in execute
    return self.cursor.execute(sql, params)
  File "/usr/local/lib/python2.7/dist-packages/django/db/utils.py", line 95, in __exit__
    six.reraise(dj_exc_type, dj_exc_value, traceback)
  File "/usr/local/lib/python2.7/dist-packages/django/db/backends/utils.py", line 64, in execute
    return self.cursor.execute(sql, params)
ProgrammingError: relation "base_v_comment" does not exist
LINE 2: from base_v_comment vc left join (select distinct comment_id...
             ^

ERROR 2016-04-08 10:26:33,083 base 24697 140716271146816 Internal Server Error: /pdf4/rpc
Traceback (most recent call last):
  File "/usr/local/lib/python2.7/dist-packages/django/core/handlers/base.py", line 149, in get_response
    response = self.process_exception_by_middleware(e, request)
  File "/usr/local/lib/python2.7/dist-packages/django/core/handlers/base.py", line 147, in get_response
    response = wrapped_callback(request, *callback_args, **callback_kwargs)
  File "/usr/local/lib/python2.7/dist-packages/django/views/decorators/csrf.py", line 58, in wrapped_view
    return view_func(*args, **kwargs)
  File "/opt/nbproject/apps/rpc/views.py", line 808, in run
    r.content = getattr(MODULE, fctname)(payload, req)
  File "/opt/nbproject/apps/rpc/views.py", line 310, in getObjects
    output[t] = getattr(annotations, "get_"+t)(uid, p2)
  File "/opt/nbproject/apps/base/annotations.py", line 275, in get_file_stats
    return  db.Db().getIndexedObjects(names, "id", from_clause, "true" , (uid,uid, uid, uid, id_ensemble))
  File "/opt/nbproject/apps/base/db.py", line 127, in getIndexedObjects
    c = self.execute(qry, args, connection)
  File "/opt/nbproject/apps/base/db.py", line 49, in execute
    cursor.execute(qry, args)
  File "/usr/local/lib/python2.7/dist-packages/django/db/backends/utils.py", line 64, in execute
    return self.cursor.execute(sql, params)
  File "/usr/local/lib/python2.7/dist-packages/django/db/utils.py", line 95, in __exit__
    six.reraise(dj_exc_type, dj_exc_value, traceback)
  File "/usr/local/lib/python2.7/dist-packages/django/db/backends/utils.py", line 64, in execute
    return self.cursor.execute(sql, params)
ProgrammingError: relation "base_v_comment" does not exist
LINE 2: from base_v_comment vc left join (select distinct comment_id...
             ^

ERROR 2016-04-08 10:26:34,108 base 24697 140716271146816 Internal Server Error: /pdf4/rpc
Traceback (most recent call last):
  File "/usr/local/lib/python2.7/dist-packages/django/core/handlers/base.py", line 149, in get_response
    response = self.process_exception_by_middleware(e, request)
  File "/usr/local/lib/python2.7/dist-packages/django/core/handlers/base.py", line 147, in get_response
    response = wrapped_callback(request, *callback_args, **callback_kwargs)
  File "/usr/local/lib/python2.7/dist-packages/django/views/decorators/csrf.py", line 58, in wrapped_view
    return view_func(*args, **kwargs)
  File "/opt/nbproject/apps/rpc/views.py", line 808, in run
    r.content = getattr(MODULE, fctname)(payload, req)
  File "/opt/nbproject/apps/rpc/views.py", line 310, in getObjects
    output[t] = getattr(annotations, "get_"+t)(uid, p2)
  File "/opt/nbproject/apps/base/annotations.py", line 275, in get_file_stats
    return  db.Db().getIndexedObjects(names, "id", from_clause, "true" , (uid,uid, uid, uid, id_ensemble))
  File "/opt/nbproject/apps/base/db.py", line 127, in getIndexedObjects
    c = self.execute(qry, args, connection)
  File "/opt/nbproject/apps/base/db.py", line 49, in execute
    cursor.execute(qry, args)
  File "/usr/local/lib/python2.7/dist-packages/django/db/backends/utils.py", line 64, in execute
    return self.cursor.execute(sql, params)
  File "/usr/local/lib/python2.7/dist-packages/django/db/utils.py", line 95, in __exit__
    six.reraise(dj_exc_type, dj_exc_value, traceback)
  File "/usr/local/lib/python2.7/dist-packages/django/db/backends/utils.py", line 64, in execute
    return self.cursor.execute(sql, params)
ProgrammingError: relation "base_v_comment" does not exist
LINE 2: from base_v_comment vc left join (select distinct comment_id...
             ^

ERROR 2016-04-08 10:27:11,239 base 24697 140716271146816 Internal Server Error: /pdf4/rpc
Traceback (most recent call last):
  File "/usr/local/lib/python2.7/dist-packages/django/core/handlers/base.py", line 149, in get_response
    response = self.process_exception_by_middleware(e, request)
  File "/usr/local/lib/python2.7/dist-packages/django/core/handlers/base.py", line 147, in get_response
    response = wrapped_callback(request, *callback_args, **callback_kwargs)
  File "/usr/local/lib/python2.7/dist-packages/django/views/decorators/csrf.py", line 58, in wrapped_view
    return view_func(*args, **kwargs)
  File "/opt/nbproject/apps/rpc/views.py", line 808, in run
    r.content = getattr(MODULE, fctname)(payload, req)
  File "/opt/nbproject/apps/rpc/views.py", line 310, in getObjects
    output[t] = getattr(annotations, "get_"+t)(uid, p2)
  File "/opt/nbproject/apps/base/annotations.py", line 275, in get_file_stats
    return  db.Db().getIndexedObjects(names, "id", from_clause, "true" , (uid,uid, uid, uid, id_ensemble))
  File "/opt/nbproject/apps/base/db.py", line 127, in getIndexedObjects
    c = self.execute(qry, args, connection)
  File "/opt/nbproject/apps/base/db.py", line 49, in execute
    cursor.execute(qry, args)
  File "/usr/local/lib/python2.7/dist-packages/django/db/backends/utils.py", line 64, in execute
    return self.cursor.execute(sql, params)
  File "/usr/local/lib/python2.7/dist-packages/django/db/utils.py", line 95, in __exit__
    six.reraise(dj_exc_type, dj_exc_value, traceback)
  File "/usr/local/lib/python2.7/dist-packages/django/db/backends/utils.py", line 64, in execute
    return self.cursor.execute(sql, params)
ProgrammingError: relation "base_v_comment" does not exist
LINE 2: from base_v_comment vc left join (select distinct comment_id...
             ^

ERROR 2016-04-08 10:28:23,105 base 24697 140716271146816 Internal Server Error: /pdf4/rpc
Traceback (most recent call last):
  File "/usr/local/lib/python2.7/dist-packages/django/core/handlers/base.py", line 149, in get_response
    response = self.process_exception_by_middleware(e, request)
  File "/usr/local/lib/python2.7/dist-packages/django/core/handlers/base.py", line 147, in get_response
    response = wrapped_callback(request, *callback_args, **callback_kwargs)
  File "/usr/local/lib/python2.7/dist-packages/django/views/decorators/csrf.py", line 58, in wrapped_view
    return view_func(*args, **kwargs)
  File "/opt/nbproject/apps/rpc/views.py", line 808, in run
    r.content = getattr(MODULE, fctname)(payload, req)
  File "/opt/nbproject/apps/rpc/views.py", line 310, in getObjects
    output[t] = getattr(annotations, "get_"+t)(uid, p2)
  File "/opt/nbproject/apps/base/annotations.py", line 275, in get_file_stats
    return  db.Db().getIndexedObjects(names, "id", from_clause, "true" , (uid,uid, uid, uid, id_ensemble))
  File "/opt/nbproject/apps/base/db.py", line 127, in getIndexedObjects
    c = self.execute(qry, args, connection)
  File "/opt/nbproject/apps/base/db.py", line 49, in execute
    cursor.execute(qry, args)
  File "/usr/local/lib/python2.7/dist-packages/django/db/backends/utils.py", line 64, in execute
    return self.cursor.execute(sql, params)
  File "/usr/local/lib/python2.7/dist-packages/django/db/utils.py", line 95, in __exit__
    six.reraise(dj_exc_type, dj_exc_value, traceback)
  File "/usr/local/lib/python2.7/dist-packages/django/db/backends/utils.py", line 64, in execute
    return self.cursor.execute(sql, params)
ProgrammingError: relation "base_v_comment" does not exist
LINE 2: from base_v_comment vc left join (select distinct comment_id...
             ^

ERROR 2016-04-08 10:28:36,036 base 24697 140716271146816 Internal Server Error: /pdf4/rpc
Traceback (most recent call last):
  File "/usr/local/lib/python2.7/dist-packages/django/core/handlers/base.py", line 149, in get_response
    response = self.process_exception_by_middleware(e, request)
  File "/usr/local/lib/python2.7/dist-packages/django/core/handlers/base.py", line 147, in get_response
    response = wrapped_callback(request, *callback_args, **callback_kwargs)
  File "/usr/local/lib/python2.7/dist-packages/django/views/decorators/csrf.py", line 58, in wrapped_view
    return view_func(*args, **kwargs)
  File "/opt/nbproject/apps/rpc/views.py", line 808, in run
    r.content = getattr(MODULE, fctname)(payload, req)
  File "/opt/nbproject/apps/rpc/views.py", line 310, in getObjects
    output[t] = getattr(annotations, "get_"+t)(uid, p2)
  File "/opt/nbproject/apps/base/annotations.py", line 275, in get_file_stats
    return  db.Db().getIndexedObjects(names, "id", from_clause, "true" , (uid,uid, uid, uid, id_ensemble))
  File "/opt/nbproject/apps/base/db.py", line 127, in getIndexedObjects
    c = self.execute(qry, args, connection)
  File "/opt/nbproject/apps/base/db.py", line 49, in execute
    cursor.execute(qry, args)
  File "/usr/local/lib/python2.7/dist-packages/django/db/backends/utils.py", line 64, in execute
    return self.cursor.execute(sql, params)
  File "/usr/local/lib/python2.7/dist-packages/django/db/utils.py", line 95, in __exit__
    six.reraise(dj_exc_type, dj_exc_value, traceback)
  File "/usr/local/lib/python2.7/dist-packages/django/db/backends/utils.py", line 64, in execute
    return self.cursor.execute(sql, params)
ProgrammingError: relation "base_v_comment" does not exist
LINE 2: from base_v_comment vc left join (select distinct comment_id...
             ^

ERROR 2016-04-08 10:29:38,442 base 24697 140716271146816 Internal Server Error: /pdf4/rpc
Traceback (most recent call last):
  File "/usr/local/lib/python2.7/dist-packages/django/core/handlers/base.py", line 149, in get_response
    response = self.process_exception_by_middleware(e, request)
  File "/usr/local/lib/python2.7/dist-packages/django/core/handlers/base.py", line 147, in get_response
    response = wrapped_callback(request, *callback_args, **callback_kwargs)
  File "/usr/local/lib/python2.7/dist-packages/django/views/decorators/csrf.py", line 58, in wrapped_view
    return view_func(*args, **kwargs)
  File "/opt/nbproject/apps/rpc/views.py", line 808, in run
    r.content = getattr(MODULE, fctname)(payload, req)
  File "/opt/nbproject/apps/rpc/views.py", line 310, in getObjects
    output[t] = getattr(annotations, "get_"+t)(uid, p2)
  File "/opt/nbproject/apps/base/annotations.py", line 275, in get_file_stats
    return  db.Db().getIndexedObjects(names, "id", from_clause, "true" , (uid,uid, uid, uid, id_ensemble))
  File "/opt/nbproject/apps/base/db.py", line 127, in getIndexedObjects
    c = self.execute(qry, args, connection)
  File "/opt/nbproject/apps/base/db.py", line 49, in execute
    cursor.execute(qry, args)
  File "/usr/local/lib/python2.7/dist-packages/django/db/backends/utils.py", line 64, in execute
    return self.cursor.execute(sql, params)
  File "/usr/local/lib/python2.7/dist-packages/django/db/utils.py", line 95, in __exit__
    six.reraise(dj_exc_type, dj_exc_value, traceback)
  File "/usr/local/lib/python2.7/dist-packages/django/db/backends/utils.py", line 64, in execute
    return self.cursor.execute(sql, params)
ProgrammingError: relation "base_v_comment" does not exist
LINE 2: from base_v_comment vc left join (select distinct comment_id...
             ^

ERROR 2016-04-08 10:35:00,937 base 24697 140716271146816 Internal Server Error: /pdf4/rpc
Traceback (most recent call last):
  File "/usr/local/lib/python2.7/dist-packages/django/core/handlers/base.py", line 149, in get_response
    response = self.process_exception_by_middleware(e, request)
  File "/usr/local/lib/python2.7/dist-packages/django/core/handlers/base.py", line 147, in get_response
    response = wrapped_callback(request, *callback_args, **callback_kwargs)
  File "/usr/local/lib/python2.7/dist-packages/django/views/decorators/csrf.py", line 58, in wrapped_view
    return view_func(*args, **kwargs)
  File "/opt/nbproject/apps/rpc/views.py", line 808, in run
    r.content = getattr(MODULE, fctname)(payload, req)
  File "/opt/nbproject/apps/rpc/views.py", line 310, in getObjects
    output[t] = getattr(annotations, "get_"+t)(uid, p2)
  File "/opt/nbproject/apps/base/annotations.py", line 275, in get_file_stats
    return  db.Db().getIndexedObjects(names, "id", from_clause, "true" , (uid,uid, uid, uid, id_ensemble))
  File "/opt/nbproject/apps/base/db.py", line 127, in getIndexedObjects
    c = self.execute(qry, args, connection)
  File "/opt/nbproject/apps/base/db.py", line 49, in execute
    cursor.execute(qry, args)
  File "/usr/local/lib/python2.7/dist-packages/django/db/backends/utils.py", line 64, in execute
    return self.cursor.execute(sql, params)
  File "/usr/local/lib/python2.7/dist-packages/django/db/utils.py", line 95, in __exit__
    six.reraise(dj_exc_type, dj_exc_value, traceback)
  File "/usr/local/lib/python2.7/dist-packages/django/db/backends/utils.py", line 64, in execute
    return self.cursor.execute(sql, params)
ProgrammingError: relation "base_v_comment" does not exist
LINE 2: from base_v_comment vc left join (select distinct comment_id...
             ^

ERROR 2016-04-08 10:40:42,967 base 24697 140716271146816 Internal Server Error: /pdf4/rpc
Traceback (most recent call last):
  File "/usr/local/lib/python2.7/dist-packages/django/core/handlers/base.py", line 149, in get_response
    response = self.process_exception_by_middleware(e, request)
  File "/usr/local/lib/python2.7/dist-packages/django/core/handlers/base.py", line 147, in get_response
    response = wrapped_callback(request, *callback_args, **callback_kwargs)
  File "/usr/local/lib/python2.7/dist-packages/django/views/decorators/csrf.py", line 58, in wrapped_view
    return view_func(*args, **kwargs)
  File "/opt/nbproject/apps/rpc/views.py", line 808, in run
    r.content = getattr(MODULE, fctname)(payload, req)
  File "/opt/nbproject/apps/rpc/views.py", line 387, in saveNote
    a = annotations.addNote(payload)
  File "/opt/nbproject/apps/base/annotations.py", line 834, in addNote
    instantTagReminder(comment, tagged_user)
  File "/opt/nbproject/apps/base/annotations.py", line 737, in instantTagReminder
    default_setting = M.DefaultSetting.objects.get(name="email_confirmation_tags")
  File "/usr/local/lib/python2.7/dist-packages/django/db/models/manager.py", line 122, in manager_method
    return getattr(self.get_queryset(), name)(*args, **kwargs)
  File "/usr/local/lib/python2.7/dist-packages/django/db/models/query.py", line 387, in get
    self.model._meta.object_name
DoesNotExist: DefaultSetting matching query does not exist.
ERROR 2016-04-08 10:41:06,368 base 24697 140716271146816 Internal Server Error: /pdf4/rpc
Traceback (most recent call last):
  File "/usr/local/lib/python2.7/dist-packages/django/core/handlers/base.py", line 149, in get_response
    response = self.process_exception_by_middleware(e, request)
  File "/usr/local/lib/python2.7/dist-packages/django/core/handlers/base.py", line 147, in get_response
    response = wrapped_callback(request, *callback_args, **callback_kwargs)
  File "/usr/local/lib/python2.7/dist-packages/django/views/decorators/csrf.py", line 58, in wrapped_view
    return view_func(*args, **kwargs)
  File "/opt/nbproject/apps/rpc/views.py", line 808, in run
    r.content = getattr(MODULE, fctname)(payload, req)
  File "/opt/nbproject/apps/rpc/views.py", line 310, in getObjects
    output[t] = getattr(annotations, "get_"+t)(uid, p2)
  File "/opt/nbproject/apps/base/annotations.py", line 275, in get_file_stats
    return  db.Db().getIndexedObjects(names, "id", from_clause, "true" , (uid,uid, uid, uid, id_ensemble))
  File "/opt/nbproject/apps/base/db.py", line 127, in getIndexedObjects
    c = self.execute(qry, args, connection)
  File "/opt/nbproject/apps/base/db.py", line 49, in execute
    cursor.execute(qry, args)
  File "/usr/local/lib/python2.7/dist-packages/django/db/backends/utils.py", line 64, in execute
    return self.cursor.execute(sql, params)
  File "/usr/local/lib/python2.7/dist-packages/django/db/utils.py", line 95, in __exit__
    six.reraise(dj_exc_type, dj_exc_value, traceback)
  File "/usr/local/lib/python2.7/dist-packages/django/db/backends/utils.py", line 64, in execute
    return self.cursor.execute(sql, params)
ProgrammingError: relation "base_v_comment" does not exist
LINE 2: from base_v_comment vc left join (select distinct comment_id...
             ^

ERROR 2016-04-08 13:50:45,897 base 14169 140658464782144 Internal Server Error: /pdf4/rpc
Traceback (most recent call last):
  File "/usr/local/lib/python2.7/dist-packages/django/core/handlers/base.py", line 149, in get_response
    response = self.process_exception_by_middleware(e, request)
  File "/usr/local/lib/python2.7/dist-packages/django/core/handlers/base.py", line 147, in get_response
    response = wrapped_callback(request, *callback_args, **callback_kwargs)
  File "/usr/local/lib/python2.7/dist-packages/django/views/decorators/csrf.py", line 58, in wrapped_view
    return view_func(*args, **kwargs)
  File "/opt/nbproject/apps/rpc/views.py", line 808, in run
    r.content = getattr(MODULE, fctname)(payload, req)
  File "/opt/nbproject/apps/rpc/views.py", line 310, in getObjects
    output[t] = getattr(annotations, "get_"+t)(uid, p2)
  File "/opt/nbproject/apps/base/annotations.py", line 275, in get_file_stats
    return  db.Db().getIndexedObjects(names, "id", from_clause, "true" , (uid,uid, uid, uid, id_ensemble))
  File "/opt/nbproject/apps/base/db.py", line 127, in getIndexedObjects
    c = self.execute(qry, args, connection)
  File "/opt/nbproject/apps/base/db.py", line 49, in execute
    cursor.execute(qry, args)
  File "/usr/local/lib/python2.7/dist-packages/django/db/backends/utils.py", line 64, in execute
    return self.cursor.execute(sql, params)
  File "/usr/local/lib/python2.7/dist-packages/django/db/utils.py", line 95, in __exit__
    six.reraise(dj_exc_type, dj_exc_value, traceback)
  File "/usr/local/lib/python2.7/dist-packages/django/db/backends/utils.py", line 64, in execute
    return self.cursor.execute(sql, params)
ProgrammingError: relation "base_v_comment" does not exist
LINE 2: from base_v_comment vc left join (select distinct comment_id...
             ^

ERROR 2016-04-08 13:51:18,810 base 14169 140658464782144 Internal Server Error: /pdf4/rpc
Traceback (most recent call last):
  File "/usr/local/lib/python2.7/dist-packages/django/core/handlers/base.py", line 149, in get_response
    response = self.process_exception_by_middleware(e, request)
  File "/usr/local/lib/python2.7/dist-packages/django/core/handlers/base.py", line 147, in get_response
    response = wrapped_callback(request, *callback_args, **callback_kwargs)
  File "/usr/local/lib/python2.7/dist-packages/django/views/decorators/csrf.py", line 58, in wrapped_view
    return view_func(*args, **kwargs)
  File "/opt/nbproject/apps/rpc/views.py", line 808, in run
    r.content = getattr(MODULE, fctname)(payload, req)
  File "/opt/nbproject/apps/rpc/views.py", line 701, in get_stats_ensemble
    retval = annotations.get_stats_ensemble(payload)
  File "/opt/nbproject/apps/base/annotations.py", line 313, in get_stats_ensemble
    retval={"stats":  db.Db().getIndexedObjects(names, "ID", from_clause, "true" , (id_ensemble,))}
  File "/opt/nbproject/apps/base/db.py", line 127, in getIndexedObjects
    c = self.execute(qry, args, connection)
  File "/opt/nbproject/apps/base/db.py", line 49, in execute
    cursor.execute(qry, args)
  File "/usr/local/lib/python2.7/dist-packages/django/db/backends/utils.py", line 64, in execute
    return self.cursor.execute(sql, params)
  File "/usr/local/lib/python2.7/dist-packages/django/db/utils.py", line 95, in __exit__
    six.reraise(dj_exc_type, dj_exc_value, traceback)
  File "/usr/local/lib/python2.7/dist-packages/django/db/backends/utils.py", line 64, in execute
    return self.cursor.execute(sql, params)
ProgrammingError: relation "base_v_comment" does not exist
LINE 1: ...t_to_array(c.body, E'\\s+'), 1)) as numwords from base_v_com...
                                                             ^

ERROR 2016-04-08 13:51:25,973 base 14169 140658464782144 Internal Server Error: /spreadsheet/download/1
Traceback (most recent call last):
  File "/usr/local/lib/python2.7/dist-packages/django/core/handlers/base.py", line 149, in get_response
    response = self.process_exception_by_middleware(e, request)
  File "/usr/local/lib/python2.7/dist-packages/django/core/handlers/base.py", line 147, in get_response
    response = wrapped_callback(request, *callback_args, **callback_kwargs)
  File "/opt/nbproject/apps/img/views.py", line 375, in serve_grades_spreadsheet
    stats = add_count_sheets(id_ensemble, wbk)
  File "/opt/nbproject/apps/img/views.py", line 182, in add_count_sheets
    a  = annotations.get_stats_ensemble({"id_ensemble": id_ensemble})
  File "/opt/nbproject/apps/base/annotations.py", line 313, in get_stats_ensemble
    retval={"stats":  db.Db().getIndexedObjects(names, "ID", from_clause, "true" , (id_ensemble,))}
  File "/opt/nbproject/apps/base/db.py", line 127, in getIndexedObjects
    c = self.execute(qry, args, connection)
  File "/opt/nbproject/apps/base/db.py", line 49, in execute
    cursor.execute(qry, args)
  File "/usr/local/lib/python2.7/dist-packages/django/db/backends/utils.py", line 64, in execute
    return self.cursor.execute(sql, params)
  File "/usr/local/lib/python2.7/dist-packages/django/db/utils.py", line 95, in __exit__
    six.reraise(dj_exc_type, dj_exc_value, traceback)
  File "/usr/local/lib/python2.7/dist-packages/django/db/backends/utils.py", line 64, in execute
    return self.cursor.execute(sql, params)
ProgrammingError: relation "base_v_comment" does not exist
LINE 1: ...t_to_array(c.body, E'\\s+'), 1)) as numwords from base_v_com...
                                                             ^

ERROR 2016-04-08 13:51:38,614 base 14169 140658464782144 Internal Server Error: /pdf4/rpc
Traceback (most recent call last):
  File "/usr/local/lib/python2.7/dist-packages/django/core/handlers/base.py", line 149, in get_response
    response = self.process_exception_by_middleware(e, request)
  File "/usr/local/lib/python2.7/dist-packages/django/core/handlers/base.py", line 147, in get_response
    response = wrapped_callback(request, *callback_args, **callback_kwargs)
  File "/usr/local/lib/python2.7/dist-packages/django/views/decorators/csrf.py", line 58, in wrapped_view
    return view_func(*args, **kwargs)
  File "/opt/nbproject/apps/rpc/views.py", line 808, in run
    r.content = getattr(MODULE, fctname)(payload, req)
  File "/opt/nbproject/apps/rpc/views.py", line 310, in getObjects
    output[t] = getattr(annotations, "get_"+t)(uid, p2)
  File "/opt/nbproject/apps/base/annotations.py", line 275, in get_file_stats
    return  db.Db().getIndexedObjects(names, "id", from_clause, "true" , (uid,uid, uid, uid, id_ensemble))
  File "/opt/nbproject/apps/base/db.py", line 127, in getIndexedObjects
    c = self.execute(qry, args, connection)
  File "/opt/nbproject/apps/base/db.py", line 49, in execute
    cursor.execute(qry, args)
  File "/usr/local/lib/python2.7/dist-packages/django/db/backends/utils.py", line 64, in execute
    return self.cursor.execute(sql, params)
  File "/usr/local/lib/python2.7/dist-packages/django/db/utils.py", line 95, in __exit__
    six.reraise(dj_exc_type, dj_exc_value, traceback)
  File "/usr/local/lib/python2.7/dist-packages/django/db/backends/utils.py", line 64, in execute
    return self.cursor.execute(sql, params)
ProgrammingError: relation "base_v_comment" does not exist
LINE 2: from base_v_comment vc left join (select distinct comment_id...
             ^

ERROR 2016-04-08 15:11:58,237 base 14169 140658464782144 Internal Server Error: /pdf4/rpc
Traceback (most recent call last):
  File "/usr/local/lib/python2.7/dist-packages/django/core/handlers/base.py", line 149, in get_response
    response = self.process_exception_by_middleware(e, request)
  File "/usr/local/lib/python2.7/dist-packages/django/core/handlers/base.py", line 147, in get_response
    response = wrapped_callback(request, *callback_args, **callback_kwargs)
  File "/usr/local/lib/python2.7/dist-packages/django/views/decorators/csrf.py", line 58, in wrapped_view
    return view_func(*args, **kwargs)
  File "/opt/nbproject/apps/rpc/views.py", line 808, in run
    r.content = getattr(MODULE, fctname)(payload, req)
  File "/opt/nbproject/apps/rpc/views.py", line 310, in getObjects
    output[t] = getattr(annotations, "get_"+t)(uid, p2)
  File "/opt/nbproject/apps/base/annotations.py", line 275, in get_file_stats
    return  db.Db().getIndexedObjects(names, "id", from_clause, "true" , (uid,uid, uid, uid, id_ensemble))
  File "/opt/nbproject/apps/base/db.py", line 127, in getIndexedObjects
    c = self.execute(qry, args, connection)
  File "/opt/nbproject/apps/base/db.py", line 49, in execute
    cursor.execute(qry, args)
  File "/usr/local/lib/python2.7/dist-packages/django/db/backends/utils.py", line 64, in execute
    return self.cursor.execute(sql, params)
  File "/usr/local/lib/python2.7/dist-packages/django/db/utils.py", line 95, in __exit__
    six.reraise(dj_exc_type, dj_exc_value, traceback)
  File "/usr/local/lib/python2.7/dist-packages/django/db/backends/utils.py", line 64, in execute
    return self.cursor.execute(sql, params)
ProgrammingError: relation "base_v_comment" does not exist
LINE 2: from base_v_comment vc left join (select distinct comment_id...
             ^

ERROR 2016-04-11 09:24:09,917 base 14169 140658464782144 Internal Server Error: /pdf4/rpc
Traceback (most recent call last):
  File "/usr/local/lib/python2.7/dist-packages/django/core/handlers/base.py", line 149, in get_response
    response = self.process_exception_by_middleware(e, request)
  File "/usr/local/lib/python2.7/dist-packages/django/core/handlers/base.py", line 147, in get_response
    response = wrapped_callback(request, *callback_args, **callback_kwargs)
  File "/usr/local/lib/python2.7/dist-packages/django/views/decorators/csrf.py", line 58, in wrapped_view
    return view_func(*args, **kwargs)
  File "/opt/nbproject/apps/rpc/views.py", line 808, in run
    r.content = getattr(MODULE, fctname)(payload, req)
  File "/opt/nbproject/apps/rpc/views.py", line 310, in getObjects
    output[t] = getattr(annotations, "get_"+t)(uid, p2)
  File "/opt/nbproject/apps/base/annotations.py", line 275, in get_file_stats
    return  db.Db().getIndexedObjects(names, "id", from_clause, "true" , (uid,uid, uid, uid, id_ensemble))
  File "/opt/nbproject/apps/base/db.py", line 127, in getIndexedObjects
    c = self.execute(qry, args, connection)
  File "/opt/nbproject/apps/base/db.py", line 49, in execute
    cursor.execute(qry, args)
  File "/usr/local/lib/python2.7/dist-packages/django/db/backends/utils.py", line 64, in execute
    return self.cursor.execute(sql, params)
  File "/usr/local/lib/python2.7/dist-packages/django/db/utils.py", line 95, in __exit__
    six.reraise(dj_exc_type, dj_exc_value, traceback)
  File "/usr/local/lib/python2.7/dist-packages/django/db/backends/utils.py", line 64, in execute
    return self.cursor.execute(sql, params)
ProgrammingError: relation "base_v_comment" does not exist
LINE 2: from base_v_comment vc left join (select distinct comment_id...
             ^

ERROR 2016-04-11 09:25:10,513 base 14169 140658464782144 Internal Server Error: /pdf4/rpc
Traceback (most recent call last):
  File "/usr/local/lib/python2.7/dist-packages/django/core/handlers/base.py", line 149, in get_response
    response = self.process_exception_by_middleware(e, request)
  File "/usr/local/lib/python2.7/dist-packages/django/core/handlers/base.py", line 147, in get_response
    response = wrapped_callback(request, *callback_args, **callback_kwargs)
  File "/usr/local/lib/python2.7/dist-packages/django/views/decorators/csrf.py", line 58, in wrapped_view
    return view_func(*args, **kwargs)
  File "/opt/nbproject/apps/rpc/views.py", line 808, in run
    r.content = getattr(MODULE, fctname)(payload, req)
  File "/opt/nbproject/apps/rpc/views.py", line 310, in getObjects
    output[t] = getattr(annotations, "get_"+t)(uid, p2)
  File "/opt/nbproject/apps/base/annotations.py", line 275, in get_file_stats
    return  db.Db().getIndexedObjects(names, "id", from_clause, "true" , (uid,uid, uid, uid, id_ensemble))
  File "/opt/nbproject/apps/base/db.py", line 127, in getIndexedObjects
    c = self.execute(qry, args, connection)
  File "/opt/nbproject/apps/base/db.py", line 49, in execute
    cursor.execute(qry, args)
  File "/usr/local/lib/python2.7/dist-packages/django/db/backends/utils.py", line 64, in execute
    return self.cursor.execute(sql, params)
  File "/usr/local/lib/python2.7/dist-packages/django/db/utils.py", line 95, in __exit__
    six.reraise(dj_exc_type, dj_exc_value, traceback)
  File "/usr/local/lib/python2.7/dist-packages/django/db/backends/utils.py", line 64, in execute
    return self.cursor.execute(sql, params)
ProgrammingError: relation "base_v_comment" does not exist
LINE 2: from base_v_comment vc left join (select distinct comment_id...
             ^

ERROR 2016-04-11 09:25:10,982 base 14169 140658464782144 Internal Server Error: /pdf4/rpc
Traceback (most recent call last):
  File "/usr/local/lib/python2.7/dist-packages/django/core/handlers/base.py", line 149, in get_response
    response = self.process_exception_by_middleware(e, request)
  File "/usr/local/lib/python2.7/dist-packages/django/core/handlers/base.py", line 147, in get_response
    response = wrapped_callback(request, *callback_args, **callback_kwargs)
  File "/usr/local/lib/python2.7/dist-packages/django/views/decorators/csrf.py", line 58, in wrapped_view
    return view_func(*args, **kwargs)
  File "/opt/nbproject/apps/rpc/views.py", line 808, in run
    r.content = getattr(MODULE, fctname)(payload, req)
  File "/opt/nbproject/apps/rpc/views.py", line 310, in getObjects
    output[t] = getattr(annotations, "get_"+t)(uid, p2)
  File "/opt/nbproject/apps/base/annotations.py", line 275, in get_file_stats
    return  db.Db().getIndexedObjects(names, "id", from_clause, "true" , (uid,uid, uid, uid, id_ensemble))
  File "/opt/nbproject/apps/base/db.py", line 127, in getIndexedObjects
    c = self.execute(qry, args, connection)
  File "/opt/nbproject/apps/base/db.py", line 49, in execute
    cursor.execute(qry, args)
  File "/usr/local/lib/python2.7/dist-packages/django/db/backends/utils.py", line 64, in execute
    return self.cursor.execute(sql, params)
  File "/usr/local/lib/python2.7/dist-packages/django/db/utils.py", line 95, in __exit__
    six.reraise(dj_exc_type, dj_exc_value, traceback)
  File "/usr/local/lib/python2.7/dist-packages/django/db/backends/utils.py", line 64, in execute
    return self.cursor.execute(sql, params)
ProgrammingError: relation "base_v_comment" does not exist
LINE 2: from base_v_comment vc left join (select distinct comment_id...
             ^

ERROR 2016-04-11 09:25:13,144 base 14169 140658464782144 Internal Server Error: /pdf4/rpc
Traceback (most recent call last):
  File "/usr/local/lib/python2.7/dist-packages/django/core/handlers/base.py", line 149, in get_response
    response = self.process_exception_by_middleware(e, request)
  File "/usr/local/lib/python2.7/dist-packages/django/core/handlers/base.py", line 147, in get_response
    response = wrapped_callback(request, *callback_args, **callback_kwargs)
  File "/usr/local/lib/python2.7/dist-packages/django/views/decorators/csrf.py", line 58, in wrapped_view
    return view_func(*args, **kwargs)
  File "/opt/nbproject/apps/rpc/views.py", line 808, in run
    r.content = getattr(MODULE, fctname)(payload, req)
  File "/opt/nbproject/apps/rpc/views.py", line 310, in getObjects
    output[t] = getattr(annotations, "get_"+t)(uid, p2)
  File "/opt/nbproject/apps/base/annotations.py", line 275, in get_file_stats
    return  db.Db().getIndexedObjects(names, "id", from_clause, "true" , (uid,uid, uid, uid, id_ensemble))
  File "/opt/nbproject/apps/base/db.py", line 127, in getIndexedObjects
    c = self.execute(qry, args, connection)
  File "/opt/nbproject/apps/base/db.py", line 49, in execute
    cursor.execute(qry, args)
  File "/usr/local/lib/python2.7/dist-packages/django/db/backends/utils.py", line 64, in execute
    return self.cursor.execute(sql, params)
  File "/usr/local/lib/python2.7/dist-packages/django/db/utils.py", line 95, in __exit__
    six.reraise(dj_exc_type, dj_exc_value, traceback)
  File "/usr/local/lib/python2.7/dist-packages/django/db/backends/utils.py", line 64, in execute
    return self.cursor.execute(sql, params)
ProgrammingError: relation "base_v_comment" does not exist
LINE 2: from base_v_comment vc left join (select distinct comment_id...
             ^

ERROR 2016-04-11 09:25:14,022 base 14169 140658464782144 Internal Server Error: /pdf4/rpc
Traceback (most recent call last):
  File "/usr/local/lib/python2.7/dist-packages/django/core/handlers/base.py", line 149, in get_response
    response = self.process_exception_by_middleware(e, request)
  File "/usr/local/lib/python2.7/dist-packages/django/core/handlers/base.py", line 147, in get_response
    response = wrapped_callback(request, *callback_args, **callback_kwargs)
  File "/usr/local/lib/python2.7/dist-packages/django/views/decorators/csrf.py", line 58, in wrapped_view
    return view_func(*args, **kwargs)
  File "/opt/nbproject/apps/rpc/views.py", line 808, in run
    r.content = getattr(MODULE, fctname)(payload, req)
  File "/opt/nbproject/apps/rpc/views.py", line 310, in getObjects
    output[t] = getattr(annotations, "get_"+t)(uid, p2)
  File "/opt/nbproject/apps/base/annotations.py", line 275, in get_file_stats
    return  db.Db().getIndexedObjects(names, "id", from_clause, "true" , (uid,uid, uid, uid, id_ensemble))
  File "/opt/nbproject/apps/base/db.py", line 127, in getIndexedObjects
    c = self.execute(qry, args, connection)
  File "/opt/nbproject/apps/base/db.py", line 49, in execute
    cursor.execute(qry, args)
  File "/usr/local/lib/python2.7/dist-packages/django/db/backends/utils.py", line 64, in execute
    return self.cursor.execute(sql, params)
  File "/usr/local/lib/python2.7/dist-packages/django/db/utils.py", line 95, in __exit__
    six.reraise(dj_exc_type, dj_exc_value, traceback)
  File "/usr/local/lib/python2.7/dist-packages/django/db/backends/utils.py", line 64, in execute
    return self.cursor.execute(sql, params)
ProgrammingError: relation "base_v_comment" does not exist
LINE 2: from base_v_comment vc left join (select distinct comment_id...
             ^

ERROR 2016-04-11 09:26:08,307 base 14169 140658464782144 Internal Server Error: /pdf4/rpc
Traceback (most recent call last):
  File "/usr/local/lib/python2.7/dist-packages/django/core/handlers/base.py", line 149, in get_response
    response = self.process_exception_by_middleware(e, request)
  File "/usr/local/lib/python2.7/dist-packages/django/core/handlers/base.py", line 147, in get_response
    response = wrapped_callback(request, *callback_args, **callback_kwargs)
  File "/usr/local/lib/python2.7/dist-packages/django/views/decorators/csrf.py", line 58, in wrapped_view
    return view_func(*args, **kwargs)
  File "/opt/nbproject/apps/rpc/views.py", line 808, in run
    r.content = getattr(MODULE, fctname)(payload, req)
  File "/opt/nbproject/apps/rpc/views.py", line 701, in get_stats_ensemble
    retval = annotations.get_stats_ensemble(payload)
  File "/opt/nbproject/apps/base/annotations.py", line 313, in get_stats_ensemble
    retval={"stats":  db.Db().getIndexedObjects(names, "ID", from_clause, "true" , (id_ensemble,))}
  File "/opt/nbproject/apps/base/db.py", line 127, in getIndexedObjects
    c = self.execute(qry, args, connection)
  File "/opt/nbproject/apps/base/db.py", line 49, in execute
    cursor.execute(qry, args)
  File "/usr/local/lib/python2.7/dist-packages/django/db/backends/utils.py", line 64, in execute
    return self.cursor.execute(sql, params)
  File "/usr/local/lib/python2.7/dist-packages/django/db/utils.py", line 95, in __exit__
    six.reraise(dj_exc_type, dj_exc_value, traceback)
  File "/usr/local/lib/python2.7/dist-packages/django/db/backends/utils.py", line 64, in execute
    return self.cursor.execute(sql, params)
ProgrammingError: relation "base_v_comment" does not exist
LINE 1: ...t_to_array(c.body, E'\\s+'), 1)) as numwords from base_v_com...
                                                             ^

ERROR 2016-04-11 09:26:11,405 base 14169 140658464782144 Internal Server Error: /spreadsheet/download/4
Traceback (most recent call last):
  File "/usr/local/lib/python2.7/dist-packages/django/core/handlers/base.py", line 149, in get_response
    response = self.process_exception_by_middleware(e, request)
  File "/usr/local/lib/python2.7/dist-packages/django/core/handlers/base.py", line 147, in get_response
    response = wrapped_callback(request, *callback_args, **callback_kwargs)
  File "/opt/nbproject/apps/img/views.py", line 375, in serve_grades_spreadsheet
    stats = add_count_sheets(id_ensemble, wbk)
  File "/opt/nbproject/apps/img/views.py", line 182, in add_count_sheets
    a  = annotations.get_stats_ensemble({"id_ensemble": id_ensemble})
  File "/opt/nbproject/apps/base/annotations.py", line 313, in get_stats_ensemble
    retval={"stats":  db.Db().getIndexedObjects(names, "ID", from_clause, "true" , (id_ensemble,))}
  File "/opt/nbproject/apps/base/db.py", line 127, in getIndexedObjects
    c = self.execute(qry, args, connection)
  File "/opt/nbproject/apps/base/db.py", line 49, in execute
    cursor.execute(qry, args)
  File "/usr/local/lib/python2.7/dist-packages/django/db/backends/utils.py", line 64, in execute
    return self.cursor.execute(sql, params)
  File "/usr/local/lib/python2.7/dist-packages/django/db/utils.py", line 95, in __exit__
    six.reraise(dj_exc_type, dj_exc_value, traceback)
  File "/usr/local/lib/python2.7/dist-packages/django/db/backends/utils.py", line 64, in execute
    return self.cursor.execute(sql, params)
ProgrammingError: relation "base_v_comment" does not exist
LINE 1: ...t_to_array(c.body, E'\\s+'), 1)) as numwords from base_v_com...
                                                             ^

ERROR 2016-04-11 09:27:50,317 base 14169 140658464782144 Internal Server Error: /pdf4/rpc
Traceback (most recent call last):
  File "/usr/local/lib/python2.7/dist-packages/django/core/handlers/base.py", line 149, in get_response
    response = self.process_exception_by_middleware(e, request)
  File "/usr/local/lib/python2.7/dist-packages/django/core/handlers/base.py", line 147, in get_response
    response = wrapped_callback(request, *callback_args, **callback_kwargs)
  File "/usr/local/lib/python2.7/dist-packages/django/views/decorators/csrf.py", line 58, in wrapped_view
    return view_func(*args, **kwargs)
  File "/opt/nbproject/apps/rpc/views.py", line 808, in run
    r.content = getattr(MODULE, fctname)(payload, req)
  File "/opt/nbproject/apps/rpc/views.py", line 701, in get_stats_ensemble
    retval = annotations.get_stats_ensemble(payload)
  File "/opt/nbproject/apps/base/annotations.py", line 313, in get_stats_ensemble
    retval={"stats":  db.Db().getIndexedObjects(names, "ID", from_clause, "true" , (id_ensemble,))}
  File "/opt/nbproject/apps/base/db.py", line 127, in getIndexedObjects
    c = self.execute(qry, args, connection)
  File "/opt/nbproject/apps/base/db.py", line 49, in execute
    cursor.execute(qry, args)
  File "/usr/local/lib/python2.7/dist-packages/django/db/backends/utils.py", line 64, in execute
    return self.cursor.execute(sql, params)
  File "/usr/local/lib/python2.7/dist-packages/django/db/utils.py", line 95, in __exit__
    six.reraise(dj_exc_type, dj_exc_value, traceback)
  File "/usr/local/lib/python2.7/dist-packages/django/db/backends/utils.py", line 64, in execute
    return self.cursor.execute(sql, params)
ProgrammingError: relation "base_v_comment" does not exist
LINE 1: ...t_to_array(c.body, E'\\s+'), 1)) as numwords from base_v_com...
                                                             ^

ERROR 2016-04-11 09:27:52,475 base 14169 140658464782144 Internal Server Error: /spreadsheet/download/4
Traceback (most recent call last):
  File "/usr/local/lib/python2.7/dist-packages/django/core/handlers/base.py", line 149, in get_response
    response = self.process_exception_by_middleware(e, request)
  File "/usr/local/lib/python2.7/dist-packages/django/core/handlers/base.py", line 147, in get_response
    response = wrapped_callback(request, *callback_args, **callback_kwargs)
  File "/opt/nbproject/apps/img/views.py", line 375, in serve_grades_spreadsheet
    stats = add_count_sheets(id_ensemble, wbk)
  File "/opt/nbproject/apps/img/views.py", line 182, in add_count_sheets
    a  = annotations.get_stats_ensemble({"id_ensemble": id_ensemble})
  File "/opt/nbproject/apps/base/annotations.py", line 313, in get_stats_ensemble
    retval={"stats":  db.Db().getIndexedObjects(names, "ID", from_clause, "true" , (id_ensemble,))}
  File "/opt/nbproject/apps/base/db.py", line 127, in getIndexedObjects
    c = self.execute(qry, args, connection)
  File "/opt/nbproject/apps/base/db.py", line 49, in execute
    cursor.execute(qry, args)
  File "/usr/local/lib/python2.7/dist-packages/django/db/backends/utils.py", line 64, in execute
    return self.cursor.execute(sql, params)
  File "/usr/local/lib/python2.7/dist-packages/django/db/utils.py", line 95, in __exit__
    six.reraise(dj_exc_type, dj_exc_value, traceback)
  File "/usr/local/lib/python2.7/dist-packages/django/db/backends/utils.py", line 64, in execute
    return self.cursor.execute(sql, params)
ProgrammingError: relation "base_v_comment" does not exist
LINE 1: ...t_to_array(c.body, E'\\s+'), 1)) as numwords from base_v_com...
                                                             ^

ERROR 2016-04-11 10:15:42,514 base 14169 140658464782144 Internal Server Error: /pdf4/rpc
Traceback (most recent call last):
  File "/usr/local/lib/python2.7/dist-packages/django/core/handlers/base.py", line 149, in get_response
    response = self.process_exception_by_middleware(e, request)
  File "/usr/local/lib/python2.7/dist-packages/django/core/handlers/base.py", line 147, in get_response
    response = wrapped_callback(request, *callback_args, **callback_kwargs)
  File "/usr/local/lib/python2.7/dist-packages/django/views/decorators/csrf.py", line 58, in wrapped_view
    return view_func(*args, **kwargs)
  File "/opt/nbproject/apps/rpc/views.py", line 808, in run
    r.content = getattr(MODULE, fctname)(payload, req)
  File "/opt/nbproject/apps/rpc/views.py", line 310, in getObjects
    output[t] = getattr(annotations, "get_"+t)(uid, p2)
  File "/opt/nbproject/apps/base/annotations.py", line 275, in get_file_stats
    return  db.Db().getIndexedObjects(names, "id", from_clause, "true" , (uid,uid, uid, uid, id_ensemble))
  File "/opt/nbproject/apps/base/db.py", line 127, in getIndexedObjects
    c = self.execute(qry, args, connection)
  File "/opt/nbproject/apps/base/db.py", line 49, in execute
    cursor.execute(qry, args)
  File "/usr/local/lib/python2.7/dist-packages/django/db/backends/utils.py", line 64, in execute
    return self.cursor.execute(sql, params)
  File "/usr/local/lib/python2.7/dist-packages/django/db/utils.py", line 95, in __exit__
    six.reraise(dj_exc_type, dj_exc_value, traceback)
  File "/usr/local/lib/python2.7/dist-packages/django/db/backends/utils.py", line 64, in execute
    return self.cursor.execute(sql, params)
ProgrammingError: relation "base_v_comment" does not exist
LINE 2: from base_v_comment vc left join (select distinct comment_id...
             ^

ERROR 2016-04-11 10:16:07,116 base 14169 140658464782144 Internal Server Error: /pdf4/rpc
Traceback (most recent call last):
  File "/usr/local/lib/python2.7/dist-packages/django/core/handlers/base.py", line 149, in get_response
    response = self.process_exception_by_middleware(e, request)
  File "/usr/local/lib/python2.7/dist-packages/django/core/handlers/base.py", line 147, in get_response
    response = wrapped_callback(request, *callback_args, **callback_kwargs)
  File "/usr/local/lib/python2.7/dist-packages/django/views/decorators/csrf.py", line 58, in wrapped_view
    return view_func(*args, **kwargs)
  File "/opt/nbproject/apps/rpc/views.py", line 808, in run
    r.content = getattr(MODULE, fctname)(payload, req)
  File "/opt/nbproject/apps/rpc/views.py", line 310, in getObjects
    output[t] = getattr(annotations, "get_"+t)(uid, p2)
  File "/opt/nbproject/apps/base/annotations.py", line 275, in get_file_stats
    return  db.Db().getIndexedObjects(names, "id", from_clause, "true" , (uid,uid, uid, uid, id_ensemble))
  File "/opt/nbproject/apps/base/db.py", line 127, in getIndexedObjects
    c = self.execute(qry, args, connection)
  File "/opt/nbproject/apps/base/db.py", line 49, in execute
    cursor.execute(qry, args)
  File "/usr/local/lib/python2.7/dist-packages/django/db/backends/utils.py", line 64, in execute
    return self.cursor.execute(sql, params)
  File "/usr/local/lib/python2.7/dist-packages/django/db/utils.py", line 95, in __exit__
    six.reraise(dj_exc_type, dj_exc_value, traceback)
  File "/usr/local/lib/python2.7/dist-packages/django/db/backends/utils.py", line 64, in execute
    return self.cursor.execute(sql, params)
ProgrammingError: relation "base_v_comment" does not exist
LINE 2: from base_v_comment vc left join (select distinct comment_id...
             ^

ERROR 2016-04-11 10:16:10,394 base 14169 140658464782144 Internal Server Error: /pdf4/rpc
Traceback (most recent call last):
  File "/usr/local/lib/python2.7/dist-packages/django/core/handlers/base.py", line 149, in get_response
    response = self.process_exception_by_middleware(e, request)
  File "/usr/local/lib/python2.7/dist-packages/django/core/handlers/base.py", line 147, in get_response
    response = wrapped_callback(request, *callback_args, **callback_kwargs)
  File "/usr/local/lib/python2.7/dist-packages/django/views/decorators/csrf.py", line 58, in wrapped_view
    return view_func(*args, **kwargs)
  File "/opt/nbproject/apps/rpc/views.py", line 808, in run
    r.content = getattr(MODULE, fctname)(payload, req)
  File "/opt/nbproject/apps/rpc/views.py", line 310, in getObjects
    output[t] = getattr(annotations, "get_"+t)(uid, p2)
  File "/opt/nbproject/apps/base/annotations.py", line 275, in get_file_stats
    return  db.Db().getIndexedObjects(names, "id", from_clause, "true" , (uid,uid, uid, uid, id_ensemble))
  File "/opt/nbproject/apps/base/db.py", line 127, in getIndexedObjects
    c = self.execute(qry, args, connection)
  File "/opt/nbproject/apps/base/db.py", line 49, in execute
    cursor.execute(qry, args)
  File "/usr/local/lib/python2.7/dist-packages/django/db/backends/utils.py", line 64, in execute
    return self.cursor.execute(sql, params)
  File "/usr/local/lib/python2.7/dist-packages/django/db/utils.py", line 95, in __exit__
    six.reraise(dj_exc_type, dj_exc_value, traceback)
  File "/usr/local/lib/python2.7/dist-packages/django/db/backends/utils.py", line 64, in execute
    return self.cursor.execute(sql, params)
ProgrammingError: relation "base_v_comment" does not exist
LINE 2: from base_v_comment vc left join (select distinct comment_id...
             ^

ERROR 2016-04-12 14:48:24,120 base 14169 140658464782144 Internal Server Error: /pdf4/rpc
Traceback (most recent call last):
  File "/usr/local/lib/python2.7/dist-packages/django/core/handlers/base.py", line 149, in get_response
    response = self.process_exception_by_middleware(e, request)
  File "/usr/local/lib/python2.7/dist-packages/django/core/handlers/base.py", line 147, in get_response
    response = wrapped_callback(request, *callback_args, **callback_kwargs)
  File "/usr/local/lib/python2.7/dist-packages/django/views/decorators/csrf.py", line 58, in wrapped_view
    return view_func(*args, **kwargs)
  File "/opt/nbproject/apps/rpc/views.py", line 808, in run
    r.content = getattr(MODULE, fctname)(payload, req)
  File "/opt/nbproject/apps/rpc/views.py", line 310, in getObjects
    output[t] = getattr(annotations, "get_"+t)(uid, p2)
  File "/opt/nbproject/apps/base/annotations.py", line 275, in get_file_stats
    return  db.Db().getIndexedObjects(names, "id", from_clause, "true" , (uid,uid, uid, uid, id_ensemble))
  File "/opt/nbproject/apps/base/db.py", line 127, in getIndexedObjects
    c = self.execute(qry, args, connection)
  File "/opt/nbproject/apps/base/db.py", line 49, in execute
    cursor.execute(qry, args)
  File "/usr/local/lib/python2.7/dist-packages/django/db/backends/utils.py", line 64, in execute
    return self.cursor.execute(sql, params)
  File "/usr/local/lib/python2.7/dist-packages/django/db/utils.py", line 95, in __exit__
    six.reraise(dj_exc_type, dj_exc_value, traceback)
  File "/usr/local/lib/python2.7/dist-packages/django/db/backends/utils.py", line 64, in execute
    return self.cursor.execute(sql, params)
ProgrammingError: relation "base_v_comment" does not exist
LINE 2: from base_v_comment vc left join (select distinct comment_id...
             ^

ERROR 2016-04-19 15:36:57,888 base 14169 140658464782144 Internal Server Error: /pdf4/rpc
Traceback (most recent call last):
  File "/usr/local/lib/python2.7/dist-packages/django/core/handlers/base.py", line 149, in get_response
    response = self.process_exception_by_middleware(e, request)
  File "/usr/local/lib/python2.7/dist-packages/django/core/handlers/base.py", line 147, in get_response
    response = wrapped_callback(request, *callback_args, **callback_kwargs)
  File "/usr/local/lib/python2.7/dist-packages/django/views/decorators/csrf.py", line 58, in wrapped_view
    return view_func(*args, **kwargs)
  File "/opt/nbproject/apps/rpc/views.py", line 808, in run
    r.content = getattr(MODULE, fctname)(payload, req)
  File "/opt/nbproject/apps/rpc/views.py", line 310, in getObjects
    output[t] = getattr(annotations, "get_"+t)(uid, p2)
  File "/opt/nbproject/apps/base/annotations.py", line 275, in get_file_stats
    return  db.Db().getIndexedObjects(names, "id", from_clause, "true" , (uid,uid, uid, uid, id_ensemble))
  File "/opt/nbproject/apps/base/db.py", line 127, in getIndexedObjects
    c = self.execute(qry, args, connection)
  File "/opt/nbproject/apps/base/db.py", line 49, in execute
    cursor.execute(qry, args)
  File "/usr/local/lib/python2.7/dist-packages/django/db/backends/utils.py", line 64, in execute
    return self.cursor.execute(sql, params)
  File "/usr/local/lib/python2.7/dist-packages/django/db/utils.py", line 95, in __exit__
    six.reraise(dj_exc_type, dj_exc_value, traceback)
  File "/usr/local/lib/python2.7/dist-packages/django/db/backends/utils.py", line 64, in execute
    return self.cursor.execute(sql, params)
ProgrammingError: relation "base_v_comment" does not exist
LINE 2: from base_v_comment vc left join (select distinct comment_id...
             ^

ERROR 2016-04-19 15:36:59,072 base 14169 140658464782144 Internal Server Error: /pdf4/rpc
Traceback (most recent call last):
  File "/usr/local/lib/python2.7/dist-packages/django/core/handlers/base.py", line 149, in get_response
    response = self.process_exception_by_middleware(e, request)
  File "/usr/local/lib/python2.7/dist-packages/django/core/handlers/base.py", line 147, in get_response
    response = wrapped_callback(request, *callback_args, **callback_kwargs)
  File "/usr/local/lib/python2.7/dist-packages/django/views/decorators/csrf.py", line 58, in wrapped_view
    return view_func(*args, **kwargs)
  File "/opt/nbproject/apps/rpc/views.py", line 808, in run
    r.content = getattr(MODULE, fctname)(payload, req)
  File "/opt/nbproject/apps/rpc/views.py", line 310, in getObjects
    output[t] = getattr(annotations, "get_"+t)(uid, p2)
  File "/opt/nbproject/apps/base/annotations.py", line 275, in get_file_stats
    return  db.Db().getIndexedObjects(names, "id", from_clause, "true" , (uid,uid, uid, uid, id_ensemble))
  File "/opt/nbproject/apps/base/db.py", line 127, in getIndexedObjects
    c = self.execute(qry, args, connection)
  File "/opt/nbproject/apps/base/db.py", line 49, in execute
    cursor.execute(qry, args)
  File "/usr/local/lib/python2.7/dist-packages/django/db/backends/utils.py", line 64, in execute
    return self.cursor.execute(sql, params)
  File "/usr/local/lib/python2.7/dist-packages/django/db/utils.py", line 95, in __exit__
    six.reraise(dj_exc_type, dj_exc_value, traceback)
  File "/usr/local/lib/python2.7/dist-packages/django/db/backends/utils.py", line 64, in execute
    return self.cursor.execute(sql, params)
ProgrammingError: relation "base_v_comment" does not exist
LINE 2: from base_v_comment vc left join (select distinct comment_id...
             ^

ERROR 2016-04-19 15:37:00,193 base 14169 140658464782144 Internal Server Error: /pdf4/rpc
Traceback (most recent call last):
  File "/usr/local/lib/python2.7/dist-packages/django/core/handlers/base.py", line 149, in get_response
    response = self.process_exception_by_middleware(e, request)
  File "/usr/local/lib/python2.7/dist-packages/django/core/handlers/base.py", line 147, in get_response
    response = wrapped_callback(request, *callback_args, **callback_kwargs)
  File "/usr/local/lib/python2.7/dist-packages/django/views/decorators/csrf.py", line 58, in wrapped_view
    return view_func(*args, **kwargs)
  File "/opt/nbproject/apps/rpc/views.py", line 808, in run
    r.content = getattr(MODULE, fctname)(payload, req)
  File "/opt/nbproject/apps/rpc/views.py", line 310, in getObjects
    output[t] = getattr(annotations, "get_"+t)(uid, p2)
  File "/opt/nbproject/apps/base/annotations.py", line 275, in get_file_stats
    return  db.Db().getIndexedObjects(names, "id", from_clause, "true" , (uid,uid, uid, uid, id_ensemble))
  File "/opt/nbproject/apps/base/db.py", line 127, in getIndexedObjects
    c = self.execute(qry, args, connection)
  File "/opt/nbproject/apps/base/db.py", line 49, in execute
    cursor.execute(qry, args)
  File "/usr/local/lib/python2.7/dist-packages/django/db/backends/utils.py", line 64, in execute
    return self.cursor.execute(sql, params)
  File "/usr/local/lib/python2.7/dist-packages/django/db/utils.py", line 95, in __exit__
    six.reraise(dj_exc_type, dj_exc_value, traceback)
  File "/usr/local/lib/python2.7/dist-packages/django/db/backends/utils.py", line 64, in execute
    return self.cursor.execute(sql, params)
ProgrammingError: relation "base_v_comment" does not exist
LINE 2: from base_v_comment vc left join (select distinct comment_id...
             ^

ERROR 2016-04-22 09:52:18,226 base 14169 140658464782144 Internal Server Error: /pdf4/rpc
Traceback (most recent call last):
  File "/usr/local/lib/python2.7/dist-packages/django/core/handlers/base.py", line 149, in get_response
    response = self.process_exception_by_middleware(e, request)
  File "/usr/local/lib/python2.7/dist-packages/django/core/handlers/base.py", line 147, in get_response
    response = wrapped_callback(request, *callback_args, **callback_kwargs)
  File "/usr/local/lib/python2.7/dist-packages/django/views/decorators/csrf.py", line 58, in wrapped_view
    return view_func(*args, **kwargs)
  File "/opt/nbproject/apps/rpc/views.py", line 808, in run
    r.content = getattr(MODULE, fctname)(payload, req)
  File "/opt/nbproject/apps/rpc/views.py", line 310, in getObjects
    output[t] = getattr(annotations, "get_"+t)(uid, p2)
  File "/opt/nbproject/apps/base/annotations.py", line 275, in get_file_stats
    return  db.Db().getIndexedObjects(names, "id", from_clause, "true" , (uid,uid, uid, uid, id_ensemble))
  File "/opt/nbproject/apps/base/db.py", line 127, in getIndexedObjects
    c = self.execute(qry, args, connection)
  File "/opt/nbproject/apps/base/db.py", line 49, in execute
    cursor.execute(qry, args)
  File "/usr/local/lib/python2.7/dist-packages/django/db/backends/utils.py", line 64, in execute
    return self.cursor.execute(sql, params)
  File "/usr/local/lib/python2.7/dist-packages/django/db/utils.py", line 95, in __exit__
    six.reraise(dj_exc_type, dj_exc_value, traceback)
  File "/usr/local/lib/python2.7/dist-packages/django/db/backends/utils.py", line 64, in execute
    return self.cursor.execute(sql, params)
ProgrammingError: relation "base_v_comment" does not exist
LINE 2: from base_v_comment vc left join (select distinct comment_id...
             ^

ERROR 2016-04-22 09:52:20,453 base 14169 140658464782144 Internal Server Error: /pdf4/rpc
Traceback (most recent call last):
  File "/usr/local/lib/python2.7/dist-packages/django/core/handlers/base.py", line 149, in get_response
    response = self.process_exception_by_middleware(e, request)
  File "/usr/local/lib/python2.7/dist-packages/django/core/handlers/base.py", line 147, in get_response
    response = wrapped_callback(request, *callback_args, **callback_kwargs)
  File "/usr/local/lib/python2.7/dist-packages/django/views/decorators/csrf.py", line 58, in wrapped_view
    return view_func(*args, **kwargs)
  File "/opt/nbproject/apps/rpc/views.py", line 808, in run
    r.content = getattr(MODULE, fctname)(payload, req)
  File "/opt/nbproject/apps/rpc/views.py", line 310, in getObjects
    output[t] = getattr(annotations, "get_"+t)(uid, p2)
  File "/opt/nbproject/apps/base/annotations.py", line 275, in get_file_stats
    return  db.Db().getIndexedObjects(names, "id", from_clause, "true" , (uid,uid, uid, uid, id_ensemble))
  File "/opt/nbproject/apps/base/db.py", line 127, in getIndexedObjects
    c = self.execute(qry, args, connection)
  File "/opt/nbproject/apps/base/db.py", line 49, in execute
    cursor.execute(qry, args)
  File "/usr/local/lib/python2.7/dist-packages/django/db/backends/utils.py", line 64, in execute
    return self.cursor.execute(sql, params)
  File "/usr/local/lib/python2.7/dist-packages/django/db/utils.py", line 95, in __exit__
    six.reraise(dj_exc_type, dj_exc_value, traceback)
  File "/usr/local/lib/python2.7/dist-packages/django/db/backends/utils.py", line 64, in execute
    return self.cursor.execute(sql, params)
ProgrammingError: relation "base_v_comment" does not exist
LINE 2: from base_v_comment vc left join (select distinct comment_id...
             ^

ERROR 2016-04-26 12:45:00,599 base 14169 140658464782144 Internal Server Error: /pdf4/rpc
Traceback (most recent call last):
  File "/usr/local/lib/python2.7/dist-packages/django/core/handlers/base.py", line 149, in get_response
    response = self.process_exception_by_middleware(e, request)
  File "/usr/local/lib/python2.7/dist-packages/django/core/handlers/base.py", line 147, in get_response
    response = wrapped_callback(request, *callback_args, **callback_kwargs)
  File "/usr/local/lib/python2.7/dist-packages/django/views/decorators/csrf.py", line 58, in wrapped_view
    return view_func(*args, **kwargs)
  File "/opt/nbproject/apps/rpc/views.py", line 808, in run
    r.content = getattr(MODULE, fctname)(payload, req)
  File "/opt/nbproject/apps/rpc/views.py", line 310, in getObjects
    output[t] = getattr(annotations, "get_"+t)(uid, p2)
  File "/opt/nbproject/apps/base/annotations.py", line 275, in get_file_stats
    return  db.Db().getIndexedObjects(names, "id", from_clause, "true" , (uid,uid, uid, uid, id_ensemble))
  File "/opt/nbproject/apps/base/db.py", line 127, in getIndexedObjects
    c = self.execute(qry, args, connection)
  File "/opt/nbproject/apps/base/db.py", line 49, in execute
    cursor.execute(qry, args)
  File "/usr/local/lib/python2.7/dist-packages/django/db/backends/utils.py", line 64, in execute
    return self.cursor.execute(sql, params)
  File "/usr/local/lib/python2.7/dist-packages/django/db/utils.py", line 95, in __exit__
    six.reraise(dj_exc_type, dj_exc_value, traceback)
  File "/usr/local/lib/python2.7/dist-packages/django/db/backends/utils.py", line 64, in execute
    return self.cursor.execute(sql, params)
ProgrammingError: relation "base_v_comment" does not exist
LINE 2: from base_v_comment vc left join (select distinct comment_id...
             ^

ERROR 2016-04-27 10:44:12,929 base 14169 140658464782144 Internal Server Error: /pdf4/rpc
Traceback (most recent call last):
  File "/usr/local/lib/python2.7/dist-packages/django/core/handlers/base.py", line 149, in get_response
    response = self.process_exception_by_middleware(e, request)
  File "/usr/local/lib/python2.7/dist-packages/django/core/handlers/base.py", line 147, in get_response
    response = wrapped_callback(request, *callback_args, **callback_kwargs)
  File "/usr/local/lib/python2.7/dist-packages/django/views/decorators/csrf.py", line 58, in wrapped_view
    return view_func(*args, **kwargs)
  File "/opt/nbproject/apps/rpc/views.py", line 808, in run
    r.content = getattr(MODULE, fctname)(payload, req)
  File "/opt/nbproject/apps/rpc/views.py", line 310, in getObjects
    output[t] = getattr(annotations, "get_"+t)(uid, p2)
  File "/opt/nbproject/apps/base/annotations.py", line 275, in get_file_stats
    return  db.Db().getIndexedObjects(names, "id", from_clause, "true" , (uid,uid, uid, uid, id_ensemble))
  File "/opt/nbproject/apps/base/db.py", line 127, in getIndexedObjects
    c = self.execute(qry, args, connection)
  File "/opt/nbproject/apps/base/db.py", line 49, in execute
    cursor.execute(qry, args)
  File "/usr/local/lib/python2.7/dist-packages/django/db/backends/utils.py", line 64, in execute
    return self.cursor.execute(sql, params)
  File "/usr/local/lib/python2.7/dist-packages/django/db/utils.py", line 95, in __exit__
    six.reraise(dj_exc_type, dj_exc_value, traceback)
  File "/usr/local/lib/python2.7/dist-packages/django/db/backends/utils.py", line 64, in execute
    return self.cursor.execute(sql, params)
ProgrammingError: relation "base_v_comment" does not exist
LINE 2: from base_v_comment vc left join (select distinct comment_id...
             ^

ERROR 2016-04-28 10:05:55,450 base 14169 140658464782144 Internal Server Error: /pdf4/rpc
Traceback (most recent call last):
  File "/usr/local/lib/python2.7/dist-packages/django/core/handlers/base.py", line 149, in get_response
    response = self.process_exception_by_middleware(e, request)
  File "/usr/local/lib/python2.7/dist-packages/django/core/handlers/base.py", line 147, in get_response
    response = wrapped_callback(request, *callback_args, **callback_kwargs)
  File "/usr/local/lib/python2.7/dist-packages/django/views/decorators/csrf.py", line 58, in wrapped_view
    return view_func(*args, **kwargs)
  File "/opt/nbproject/apps/rpc/views.py", line 808, in run
    r.content = getattr(MODULE, fctname)(payload, req)
  File "/opt/nbproject/apps/rpc/views.py", line 310, in getObjects
    output[t] = getattr(annotations, "get_"+t)(uid, p2)
  File "/opt/nbproject/apps/base/annotations.py", line 275, in get_file_stats
    return  db.Db().getIndexedObjects(names, "id", from_clause, "true" , (uid,uid, uid, uid, id_ensemble))
  File "/opt/nbproject/apps/base/db.py", line 127, in getIndexedObjects
    c = self.execute(qry, args, connection)
  File "/opt/nbproject/apps/base/db.py", line 49, in execute
    cursor.execute(qry, args)
  File "/usr/local/lib/python2.7/dist-packages/django/db/backends/utils.py", line 64, in execute
    return self.cursor.execute(sql, params)
  File "/usr/local/lib/python2.7/dist-packages/django/db/utils.py", line 95, in __exit__
    six.reraise(dj_exc_type, dj_exc_value, traceback)
  File "/usr/local/lib/python2.7/dist-packages/django/db/backends/utils.py", line 64, in execute
    return self.cursor.execute(sql, params)
ProgrammingError: relation "base_v_comment" does not exist
LINE 2: from base_v_comment vc left join (select distinct comment_id...
             ^

ERROR 2016-04-28 16:33:47,588 base 14169 140658464782144 Internal Server Error: /pdf4/rpc
Traceback (most recent call last):
  File "/usr/local/lib/python2.7/dist-packages/django/core/handlers/base.py", line 149, in get_response
    response = self.process_exception_by_middleware(e, request)
  File "/usr/local/lib/python2.7/dist-packages/django/core/handlers/base.py", line 147, in get_response
    response = wrapped_callback(request, *callback_args, **callback_kwargs)
  File "/usr/local/lib/python2.7/dist-packages/django/views/decorators/csrf.py", line 58, in wrapped_view
    return view_func(*args, **kwargs)
  File "/opt/nbproject/apps/rpc/views.py", line 808, in run
    r.content = getattr(MODULE, fctname)(payload, req)
  File "/opt/nbproject/apps/rpc/views.py", line 310, in getObjects
    output[t] = getattr(annotations, "get_"+t)(uid, p2)
  File "/opt/nbproject/apps/base/annotations.py", line 275, in get_file_stats
    return  db.Db().getIndexedObjects(names, "id", from_clause, "true" , (uid,uid, uid, uid, id_ensemble))
  File "/opt/nbproject/apps/base/db.py", line 127, in getIndexedObjects
    c = self.execute(qry, args, connection)
  File "/opt/nbproject/apps/base/db.py", line 49, in execute
    cursor.execute(qry, args)
  File "/usr/local/lib/python2.7/dist-packages/django/db/backends/utils.py", line 64, in execute
    return self.cursor.execute(sql, params)
  File "/usr/local/lib/python2.7/dist-packages/django/db/utils.py", line 95, in __exit__
    six.reraise(dj_exc_type, dj_exc_value, traceback)
  File "/usr/local/lib/python2.7/dist-packages/django/db/backends/utils.py", line 64, in execute
    return self.cursor.execute(sql, params)
ProgrammingError: relation "base_v_comment" does not exist
LINE 2: from base_v_comment vc left join (select distinct comment_id...
             ^

ERROR 2016-04-28 16:33:48,188 base 14169 140658464782144 Internal Server Error: /pdf4/rpc
Traceback (most recent call last):
  File "/usr/local/lib/python2.7/dist-packages/django/core/handlers/base.py", line 149, in get_response
    response = self.process_exception_by_middleware(e, request)
  File "/usr/local/lib/python2.7/dist-packages/django/core/handlers/base.py", line 147, in get_response
    response = wrapped_callback(request, *callback_args, **callback_kwargs)
  File "/usr/local/lib/python2.7/dist-packages/django/views/decorators/csrf.py", line 58, in wrapped_view
    return view_func(*args, **kwargs)
  File "/opt/nbproject/apps/rpc/views.py", line 808, in run
    r.content = getattr(MODULE, fctname)(payload, req)
  File "/opt/nbproject/apps/rpc/views.py", line 310, in getObjects
    output[t] = getattr(annotations, "get_"+t)(uid, p2)
  File "/opt/nbproject/apps/base/annotations.py", line 275, in get_file_stats
    return  db.Db().getIndexedObjects(names, "id", from_clause, "true" , (uid,uid, uid, uid, id_ensemble))
  File "/opt/nbproject/apps/base/db.py", line 127, in getIndexedObjects
    c = self.execute(qry, args, connection)
  File "/opt/nbproject/apps/base/db.py", line 49, in execute
    cursor.execute(qry, args)
  File "/usr/local/lib/python2.7/dist-packages/django/db/backends/utils.py", line 64, in execute
    return self.cursor.execute(sql, params)
  File "/usr/local/lib/python2.7/dist-packages/django/db/utils.py", line 95, in __exit__
    six.reraise(dj_exc_type, dj_exc_value, traceback)
  File "/usr/local/lib/python2.7/dist-packages/django/db/backends/utils.py", line 64, in execute
    return self.cursor.execute(sql, params)
ProgrammingError: relation "base_v_comment" does not exist
LINE 2: from base_v_comment vc left join (select distinct comment_id...
             ^

ERROR 2016-04-28 16:34:25,833 base 14169 140658464782144 Internal Server Error: /pdf4/rpc
Traceback (most recent call last):
  File "/usr/local/lib/python2.7/dist-packages/django/core/handlers/base.py", line 149, in get_response
    response = self.process_exception_by_middleware(e, request)
  File "/usr/local/lib/python2.7/dist-packages/django/core/handlers/base.py", line 147, in get_response
    response = wrapped_callback(request, *callback_args, **callback_kwargs)
  File "/usr/local/lib/python2.7/dist-packages/django/views/decorators/csrf.py", line 58, in wrapped_view
    return view_func(*args, **kwargs)
  File "/opt/nbproject/apps/rpc/views.py", line 808, in run
    r.content = getattr(MODULE, fctname)(payload, req)
  File "/opt/nbproject/apps/rpc/views.py", line 310, in getObjects
    output[t] = getattr(annotations, "get_"+t)(uid, p2)
  File "/opt/nbproject/apps/base/annotations.py", line 275, in get_file_stats
    return  db.Db().getIndexedObjects(names, "id", from_clause, "true" , (uid,uid, uid, uid, id_ensemble))
  File "/opt/nbproject/apps/base/db.py", line 127, in getIndexedObjects
    c = self.execute(qry, args, connection)
  File "/opt/nbproject/apps/base/db.py", line 49, in execute
    cursor.execute(qry, args)
  File "/usr/local/lib/python2.7/dist-packages/django/db/backends/utils.py", line 64, in execute
    return self.cursor.execute(sql, params)
  File "/usr/local/lib/python2.7/dist-packages/django/db/utils.py", line 95, in __exit__
    six.reraise(dj_exc_type, dj_exc_value, traceback)
  File "/usr/local/lib/python2.7/dist-packages/django/db/backends/utils.py", line 64, in execute
    return self.cursor.execute(sql, params)
ProgrammingError: relation "base_v_comment" does not exist
LINE 2: from base_v_comment vc left join (select distinct comment_id...
             ^

ERROR 2016-04-28 16:34:26,833 base 14169 140658464782144 Internal Server Error: /pdf4/rpc
Traceback (most recent call last):
  File "/usr/local/lib/python2.7/dist-packages/django/core/handlers/base.py", line 149, in get_response
    response = self.process_exception_by_middleware(e, request)
  File "/usr/local/lib/python2.7/dist-packages/django/core/handlers/base.py", line 147, in get_response
    response = wrapped_callback(request, *callback_args, **callback_kwargs)
  File "/usr/local/lib/python2.7/dist-packages/django/views/decorators/csrf.py", line 58, in wrapped_view
    return view_func(*args, **kwargs)
  File "/opt/nbproject/apps/rpc/views.py", line 808, in run
    r.content = getattr(MODULE, fctname)(payload, req)
  File "/opt/nbproject/apps/rpc/views.py", line 310, in getObjects
    output[t] = getattr(annotations, "get_"+t)(uid, p2)
  File "/opt/nbproject/apps/base/annotations.py", line 275, in get_file_stats
    return  db.Db().getIndexedObjects(names, "id", from_clause, "true" , (uid,uid, uid, uid, id_ensemble))
  File "/opt/nbproject/apps/base/db.py", line 127, in getIndexedObjects
    c = self.execute(qry, args, connection)
  File "/opt/nbproject/apps/base/db.py", line 49, in execute
    cursor.execute(qry, args)
  File "/usr/local/lib/python2.7/dist-packages/django/db/backends/utils.py", line 64, in execute
    return self.cursor.execute(sql, params)
  File "/usr/local/lib/python2.7/dist-packages/django/db/utils.py", line 95, in __exit__
    six.reraise(dj_exc_type, dj_exc_value, traceback)
  File "/usr/local/lib/python2.7/dist-packages/django/db/backends/utils.py", line 64, in execute
    return self.cursor.execute(sql, params)
ProgrammingError: relation "base_v_comment" does not exist
LINE 2: from base_v_comment vc left join (select distinct comment_id...
             ^

ERROR 2016-04-28 16:34:30,807 base 14169 140658464782144 Internal Server Error: /pdf4/rpc
Traceback (most recent call last):
  File "/usr/local/lib/python2.7/dist-packages/django/core/handlers/base.py", line 149, in get_response
    response = self.process_exception_by_middleware(e, request)
  File "/usr/local/lib/python2.7/dist-packages/django/core/handlers/base.py", line 147, in get_response
    response = wrapped_callback(request, *callback_args, **callback_kwargs)
  File "/usr/local/lib/python2.7/dist-packages/django/views/decorators/csrf.py", line 58, in wrapped_view
    return view_func(*args, **kwargs)
  File "/opt/nbproject/apps/rpc/views.py", line 808, in run
    r.content = getattr(MODULE, fctname)(payload, req)
  File "/opt/nbproject/apps/rpc/views.py", line 310, in getObjects
    output[t] = getattr(annotations, "get_"+t)(uid, p2)
  File "/opt/nbproject/apps/base/annotations.py", line 275, in get_file_stats
    return  db.Db().getIndexedObjects(names, "id", from_clause, "true" , (uid,uid, uid, uid, id_ensemble))
  File "/opt/nbproject/apps/base/db.py", line 127, in getIndexedObjects
    c = self.execute(qry, args, connection)
  File "/opt/nbproject/apps/base/db.py", line 49, in execute
    cursor.execute(qry, args)
  File "/usr/local/lib/python2.7/dist-packages/django/db/backends/utils.py", line 64, in execute
    return self.cursor.execute(sql, params)
  File "/usr/local/lib/python2.7/dist-packages/django/db/utils.py", line 95, in __exit__
    six.reraise(dj_exc_type, dj_exc_value, traceback)
  File "/usr/local/lib/python2.7/dist-packages/django/db/backends/utils.py", line 64, in execute
    return self.cursor.execute(sql, params)
ProgrammingError: relation "base_v_comment" does not exist
LINE 2: from base_v_comment vc left join (select distinct comment_id...
             ^

ERROR 2016-04-29 11:12:08,405 base 14169 140658464782144 Internal Server Error: /pdf4/rpc
Traceback (most recent call last):
  File "/usr/local/lib/python2.7/dist-packages/django/core/handlers/base.py", line 149, in get_response
    response = self.process_exception_by_middleware(e, request)
  File "/usr/local/lib/python2.7/dist-packages/django/core/handlers/base.py", line 147, in get_response
    response = wrapped_callback(request, *callback_args, **callback_kwargs)
  File "/usr/local/lib/python2.7/dist-packages/django/views/decorators/csrf.py", line 58, in wrapped_view
    return view_func(*args, **kwargs)
  File "/opt/nbproject/apps/rpc/views.py", line 808, in run
    r.content = getattr(MODULE, fctname)(payload, req)
  File "/opt/nbproject/apps/rpc/views.py", line 310, in getObjects
    output[t] = getattr(annotations, "get_"+t)(uid, p2)
  File "/opt/nbproject/apps/base/annotations.py", line 275, in get_file_stats
    return  db.Db().getIndexedObjects(names, "id", from_clause, "true" , (uid,uid, uid, uid, id_ensemble))
  File "/opt/nbproject/apps/base/db.py", line 127, in getIndexedObjects
    c = self.execute(qry, args, connection)
  File "/opt/nbproject/apps/base/db.py", line 49, in execute
    cursor.execute(qry, args)
  File "/usr/local/lib/python2.7/dist-packages/django/db/backends/utils.py", line 64, in execute
    return self.cursor.execute(sql, params)
  File "/usr/local/lib/python2.7/dist-packages/django/db/utils.py", line 95, in __exit__
    six.reraise(dj_exc_type, dj_exc_value, traceback)
  File "/usr/local/lib/python2.7/dist-packages/django/db/backends/utils.py", line 64, in execute
    return self.cursor.execute(sql, params)
ProgrammingError: relation "base_v_comment" does not exist
LINE 2: from base_v_comment vc left join (select distinct comment_id...
             ^

ERROR 2016-04-29 11:12:09,568 base 14169 140658464782144 Internal Server Error: /pdf4/rpc
Traceback (most recent call last):
  File "/usr/local/lib/python2.7/dist-packages/django/core/handlers/base.py", line 149, in get_response
    response = self.process_exception_by_middleware(e, request)
  File "/usr/local/lib/python2.7/dist-packages/django/core/handlers/base.py", line 147, in get_response
    response = wrapped_callback(request, *callback_args, **callback_kwargs)
  File "/usr/local/lib/python2.7/dist-packages/django/views/decorators/csrf.py", line 58, in wrapped_view
    return view_func(*args, **kwargs)
  File "/opt/nbproject/apps/rpc/views.py", line 808, in run
    r.content = getattr(MODULE, fctname)(payload, req)
  File "/opt/nbproject/apps/rpc/views.py", line 310, in getObjects
    output[t] = getattr(annotations, "get_"+t)(uid, p2)
  File "/opt/nbproject/apps/base/annotations.py", line 275, in get_file_stats
    return  db.Db().getIndexedObjects(names, "id", from_clause, "true" , (uid,uid, uid, uid, id_ensemble))
  File "/opt/nbproject/apps/base/db.py", line 127, in getIndexedObjects
    c = self.execute(qry, args, connection)
  File "/opt/nbproject/apps/base/db.py", line 49, in execute
    cursor.execute(qry, args)
  File "/usr/local/lib/python2.7/dist-packages/django/db/backends/utils.py", line 64, in execute
    return self.cursor.execute(sql, params)
  File "/usr/local/lib/python2.7/dist-packages/django/db/utils.py", line 95, in __exit__
    six.reraise(dj_exc_type, dj_exc_value, traceback)
  File "/usr/local/lib/python2.7/dist-packages/django/db/backends/utils.py", line 64, in execute
    return self.cursor.execute(sql, params)
ProgrammingError: relation "base_v_comment" does not exist
LINE 2: from base_v_comment vc left join (select distinct comment_id...
             ^

ERROR 2016-04-29 11:12:10,490 base 14169 140658464782144 Internal Server Error: /pdf4/rpc
Traceback (most recent call last):
  File "/usr/local/lib/python2.7/dist-packages/django/core/handlers/base.py", line 149, in get_response
    response = self.process_exception_by_middleware(e, request)
  File "/usr/local/lib/python2.7/dist-packages/django/core/handlers/base.py", line 147, in get_response
    response = wrapped_callback(request, *callback_args, **callback_kwargs)
  File "/usr/local/lib/python2.7/dist-packages/django/views/decorators/csrf.py", line 58, in wrapped_view
    return view_func(*args, **kwargs)
  File "/opt/nbproject/apps/rpc/views.py", line 808, in run
    r.content = getattr(MODULE, fctname)(payload, req)
  File "/opt/nbproject/apps/rpc/views.py", line 310, in getObjects
    output[t] = getattr(annotations, "get_"+t)(uid, p2)
  File "/opt/nbproject/apps/base/annotations.py", line 275, in get_file_stats
    return  db.Db().getIndexedObjects(names, "id", from_clause, "true" , (uid,uid, uid, uid, id_ensemble))
  File "/opt/nbproject/apps/base/db.py", line 127, in getIndexedObjects
    c = self.execute(qry, args, connection)
  File "/opt/nbproject/apps/base/db.py", line 49, in execute
    cursor.execute(qry, args)
  File "/usr/local/lib/python2.7/dist-packages/django/db/backends/utils.py", line 64, in execute
    return self.cursor.execute(sql, params)
  File "/usr/local/lib/python2.7/dist-packages/django/db/utils.py", line 95, in __exit__
    six.reraise(dj_exc_type, dj_exc_value, traceback)
  File "/usr/local/lib/python2.7/dist-packages/django/db/backends/utils.py", line 64, in execute
    return self.cursor.execute(sql, params)
ProgrammingError: relation "base_v_comment" does not exist
LINE 2: from base_v_comment vc left join (select distinct comment_id...
             ^

ERROR 2016-04-29 11:12:11,491 base 14169 140658464782144 Internal Server Error: /pdf4/rpc
Traceback (most recent call last):
  File "/usr/local/lib/python2.7/dist-packages/django/core/handlers/base.py", line 149, in get_response
    response = self.process_exception_by_middleware(e, request)
  File "/usr/local/lib/python2.7/dist-packages/django/core/handlers/base.py", line 147, in get_response
    response = wrapped_callback(request, *callback_args, **callback_kwargs)
  File "/usr/local/lib/python2.7/dist-packages/django/views/decorators/csrf.py", line 58, in wrapped_view
    return view_func(*args, **kwargs)
  File "/opt/nbproject/apps/rpc/views.py", line 808, in run
    r.content = getattr(MODULE, fctname)(payload, req)
  File "/opt/nbproject/apps/rpc/views.py", line 310, in getObjects
    output[t] = getattr(annotations, "get_"+t)(uid, p2)
  File "/opt/nbproject/apps/base/annotations.py", line 275, in get_file_stats
    return  db.Db().getIndexedObjects(names, "id", from_clause, "true" , (uid,uid, uid, uid, id_ensemble))
  File "/opt/nbproject/apps/base/db.py", line 127, in getIndexedObjects
    c = self.execute(qry, args, connection)
  File "/opt/nbproject/apps/base/db.py", line 49, in execute
    cursor.execute(qry, args)
  File "/usr/local/lib/python2.7/dist-packages/django/db/backends/utils.py", line 64, in execute
    return self.cursor.execute(sql, params)
  File "/usr/local/lib/python2.7/dist-packages/django/db/utils.py", line 95, in __exit__
    six.reraise(dj_exc_type, dj_exc_value, traceback)
  File "/usr/local/lib/python2.7/dist-packages/django/db/backends/utils.py", line 64, in execute
    return self.cursor.execute(sql, params)
ProgrammingError: relation "base_v_comment" does not exist
LINE 2: from base_v_comment vc left join (select distinct comment_id...
             ^

ERROR 2016-04-29 11:12:56,010 base 14169 140658464782144 Internal Server Error: /pdf4/rpc
Traceback (most recent call last):
  File "/usr/local/lib/python2.7/dist-packages/django/core/handlers/base.py", line 149, in get_response
    response = self.process_exception_by_middleware(e, request)
  File "/usr/local/lib/python2.7/dist-packages/django/core/handlers/base.py", line 147, in get_response
    response = wrapped_callback(request, *callback_args, **callback_kwargs)
  File "/usr/local/lib/python2.7/dist-packages/django/views/decorators/csrf.py", line 58, in wrapped_view
    return view_func(*args, **kwargs)
  File "/opt/nbproject/apps/rpc/views.py", line 808, in run
    r.content = getattr(MODULE, fctname)(payload, req)
  File "/opt/nbproject/apps/rpc/views.py", line 310, in getObjects
    output[t] = getattr(annotations, "get_"+t)(uid, p2)
  File "/opt/nbproject/apps/base/annotations.py", line 275, in get_file_stats
    return  db.Db().getIndexedObjects(names, "id", from_clause, "true" , (uid,uid, uid, uid, id_ensemble))
  File "/opt/nbproject/apps/base/db.py", line 127, in getIndexedObjects
    c = self.execute(qry, args, connection)
  File "/opt/nbproject/apps/base/db.py", line 49, in execute
    cursor.execute(qry, args)
  File "/usr/local/lib/python2.7/dist-packages/django/db/backends/utils.py", line 64, in execute
    return self.cursor.execute(sql, params)
  File "/usr/local/lib/python2.7/dist-packages/django/db/utils.py", line 95, in __exit__
    six.reraise(dj_exc_type, dj_exc_value, traceback)
  File "/usr/local/lib/python2.7/dist-packages/django/db/backends/utils.py", line 64, in execute
    return self.cursor.execute(sql, params)
ProgrammingError: relation "base_v_comment" does not exist
LINE 2: from base_v_comment vc left join (select distinct comment_id...
             ^

ERROR 2016-04-29 11:26:04,793 base 14169 140658464782144 Internal Server Error: /pdf4/rpc
Traceback (most recent call last):
  File "/usr/local/lib/python2.7/dist-packages/django/core/handlers/base.py", line 149, in get_response
    response = self.process_exception_by_middleware(e, request)
  File "/usr/local/lib/python2.7/dist-packages/django/core/handlers/base.py", line 147, in get_response
    response = wrapped_callback(request, *callback_args, **callback_kwargs)
  File "/usr/local/lib/python2.7/dist-packages/django/views/decorators/csrf.py", line 58, in wrapped_view
    return view_func(*args, **kwargs)
  File "/opt/nbproject/apps/rpc/views.py", line 808, in run
    r.content = getattr(MODULE, fctname)(payload, req)
  File "/opt/nbproject/apps/rpc/views.py", line 310, in getObjects
    output[t] = getattr(annotations, "get_"+t)(uid, p2)
  File "/opt/nbproject/apps/base/annotations.py", line 275, in get_file_stats
    return  db.Db().getIndexedObjects(names, "id", from_clause, "true" , (uid,uid, uid, uid, id_ensemble))
  File "/opt/nbproject/apps/base/db.py", line 127, in getIndexedObjects
    c = self.execute(qry, args, connection)
  File "/opt/nbproject/apps/base/db.py", line 49, in execute
    cursor.execute(qry, args)
  File "/usr/local/lib/python2.7/dist-packages/django/db/backends/utils.py", line 64, in execute
    return self.cursor.execute(sql, params)
  File "/usr/local/lib/python2.7/dist-packages/django/db/utils.py", line 95, in __exit__
    six.reraise(dj_exc_type, dj_exc_value, traceback)
  File "/usr/local/lib/python2.7/dist-packages/django/db/backends/utils.py", line 64, in execute
    return self.cursor.execute(sql, params)
ProgrammingError: relation "base_v_comment" does not exist
LINE 2: from base_v_comment vc left join (select distinct comment_id...
             ^

ERROR 2016-04-29 11:26:05,616 base 14169 140658464782144 Internal Server Error: /pdf4/rpc
Traceback (most recent call last):
  File "/usr/local/lib/python2.7/dist-packages/django/core/handlers/base.py", line 149, in get_response
    response = self.process_exception_by_middleware(e, request)
  File "/usr/local/lib/python2.7/dist-packages/django/core/handlers/base.py", line 147, in get_response
    response = wrapped_callback(request, *callback_args, **callback_kwargs)
  File "/usr/local/lib/python2.7/dist-packages/django/views/decorators/csrf.py", line 58, in wrapped_view
    return view_func(*args, **kwargs)
  File "/opt/nbproject/apps/rpc/views.py", line 808, in run
    r.content = getattr(MODULE, fctname)(payload, req)
  File "/opt/nbproject/apps/rpc/views.py", line 310, in getObjects
    output[t] = getattr(annotations, "get_"+t)(uid, p2)
  File "/opt/nbproject/apps/base/annotations.py", line 275, in get_file_stats
    return  db.Db().getIndexedObjects(names, "id", from_clause, "true" , (uid,uid, uid, uid, id_ensemble))
  File "/opt/nbproject/apps/base/db.py", line 127, in getIndexedObjects
    c = self.execute(qry, args, connection)
  File "/opt/nbproject/apps/base/db.py", line 49, in execute
    cursor.execute(qry, args)
  File "/usr/local/lib/python2.7/dist-packages/django/db/backends/utils.py", line 64, in execute
    return self.cursor.execute(sql, params)
  File "/usr/local/lib/python2.7/dist-packages/django/db/utils.py", line 95, in __exit__
    six.reraise(dj_exc_type, dj_exc_value, traceback)
  File "/usr/local/lib/python2.7/dist-packages/django/db/backends/utils.py", line 64, in execute
    return self.cursor.execute(sql, params)
ProgrammingError: relation "base_v_comment" does not exist
LINE 2: from base_v_comment vc left join (select distinct comment_id...
             ^

ERROR 2016-04-29 11:47:04,617 base 14169 140658464782144 Internal Server Error: /pdf4/rpc
Traceback (most recent call last):
  File "/usr/local/lib/python2.7/dist-packages/django/core/handlers/base.py", line 149, in get_response
    response = self.process_exception_by_middleware(e, request)
  File "/usr/local/lib/python2.7/dist-packages/django/core/handlers/base.py", line 147, in get_response
    response = wrapped_callback(request, *callback_args, **callback_kwargs)
  File "/usr/local/lib/python2.7/dist-packages/django/views/decorators/csrf.py", line 58, in wrapped_view
    return view_func(*args, **kwargs)
  File "/opt/nbproject/apps/rpc/views.py", line 808, in run
    r.content = getattr(MODULE, fctname)(payload, req)
  File "/opt/nbproject/apps/rpc/views.py", line 310, in getObjects
    output[t] = getattr(annotations, "get_"+t)(uid, p2)
  File "/opt/nbproject/apps/base/annotations.py", line 275, in get_file_stats
    return  db.Db().getIndexedObjects(names, "id", from_clause, "true" , (uid,uid, uid, uid, id_ensemble))
  File "/opt/nbproject/apps/base/db.py", line 127, in getIndexedObjects
    c = self.execute(qry, args, connection)
  File "/opt/nbproject/apps/base/db.py", line 49, in execute
    cursor.execute(qry, args)
  File "/usr/local/lib/python2.7/dist-packages/django/db/backends/utils.py", line 64, in execute
    return self.cursor.execute(sql, params)
  File "/usr/local/lib/python2.7/dist-packages/django/db/utils.py", line 95, in __exit__
    six.reraise(dj_exc_type, dj_exc_value, traceback)
  File "/usr/local/lib/python2.7/dist-packages/django/db/backends/utils.py", line 64, in execute
    return self.cursor.execute(sql, params)
ProgrammingError: relation "base_v_comment" does not exist
LINE 2: from base_v_comment vc left join (select distinct comment_id...
             ^

ERROR 2016-05-02 10:40:09,550 base 14169 140658464782144 Internal Server Error: /pdf4/rpc
Traceback (most recent call last):
  File "/usr/local/lib/python2.7/dist-packages/django/core/handlers/base.py", line 149, in get_response
    response = self.process_exception_by_middleware(e, request)
  File "/usr/local/lib/python2.7/dist-packages/django/core/handlers/base.py", line 147, in get_response
    response = wrapped_callback(request, *callback_args, **callback_kwargs)
  File "/usr/local/lib/python2.7/dist-packages/django/views/decorators/csrf.py", line 58, in wrapped_view
    return view_func(*args, **kwargs)
  File "/opt/nbproject/apps/rpc/views.py", line 808, in run
    r.content = getattr(MODULE, fctname)(payload, req)
  File "/opt/nbproject/apps/rpc/views.py", line 310, in getObjects
    output[t] = getattr(annotations, "get_"+t)(uid, p2)
  File "/opt/nbproject/apps/base/annotations.py", line 275, in get_file_stats
    return  db.Db().getIndexedObjects(names, "id", from_clause, "true" , (uid,uid, uid, uid, id_ensemble))
  File "/opt/nbproject/apps/base/db.py", line 127, in getIndexedObjects
    c = self.execute(qry, args, connection)
  File "/opt/nbproject/apps/base/db.py", line 49, in execute
    cursor.execute(qry, args)
  File "/usr/local/lib/python2.7/dist-packages/django/db/backends/utils.py", line 64, in execute
    return self.cursor.execute(sql, params)
  File "/usr/local/lib/python2.7/dist-packages/django/db/utils.py", line 95, in __exit__
    six.reraise(dj_exc_type, dj_exc_value, traceback)
  File "/usr/local/lib/python2.7/dist-packages/django/db/backends/utils.py", line 64, in execute
    return self.cursor.execute(sql, params)
ProgrammingError: relation "base_v_comment" does not exist
LINE 2: from base_v_comment vc left join (select distinct comment_id...
             ^

ERROR 2016-05-02 10:42:18,698 base 14169 140658464782144 Internal Server Error: /pdf4/rpc
Traceback (most recent call last):
  File "/usr/local/lib/python2.7/dist-packages/django/core/handlers/base.py", line 149, in get_response
    response = self.process_exception_by_middleware(e, request)
  File "/usr/local/lib/python2.7/dist-packages/django/core/handlers/base.py", line 147, in get_response
    response = wrapped_callback(request, *callback_args, **callback_kwargs)
  File "/usr/local/lib/python2.7/dist-packages/django/views/decorators/csrf.py", line 58, in wrapped_view
    return view_func(*args, **kwargs)
  File "/opt/nbproject/apps/rpc/views.py", line 808, in run
    r.content = getattr(MODULE, fctname)(payload, req)
  File "/opt/nbproject/apps/rpc/views.py", line 310, in getObjects
    output[t] = getattr(annotations, "get_"+t)(uid, p2)
  File "/opt/nbproject/apps/base/annotations.py", line 275, in get_file_stats
    return  db.Db().getIndexedObjects(names, "id", from_clause, "true" , (uid,uid, uid, uid, id_ensemble))
  File "/opt/nbproject/apps/base/db.py", line 127, in getIndexedObjects
    c = self.execute(qry, args, connection)
  File "/opt/nbproject/apps/base/db.py", line 49, in execute
    cursor.execute(qry, args)
  File "/usr/local/lib/python2.7/dist-packages/django/db/backends/utils.py", line 64, in execute
    return self.cursor.execute(sql, params)
  File "/usr/local/lib/python2.7/dist-packages/django/db/utils.py", line 95, in __exit__
    six.reraise(dj_exc_type, dj_exc_value, traceback)
  File "/usr/local/lib/python2.7/dist-packages/django/db/backends/utils.py", line 64, in execute
    return self.cursor.execute(sql, params)
ProgrammingError: relation "base_v_comment" does not exist
LINE 2: from base_v_comment vc left join (select distinct comment_id...
             ^

ERROR 2016-05-04 14:13:11,127 base 14169 140658464782144 Internal Server Error: /pdf4/rpc
Traceback (most recent call last):
  File "/usr/local/lib/python2.7/dist-packages/django/core/handlers/base.py", line 149, in get_response
    response = self.process_exception_by_middleware(e, request)
  File "/usr/local/lib/python2.7/dist-packages/django/core/handlers/base.py", line 147, in get_response
    response = wrapped_callback(request, *callback_args, **callback_kwargs)
  File "/usr/local/lib/python2.7/dist-packages/django/views/decorators/csrf.py", line 58, in wrapped_view
    return view_func(*args, **kwargs)
  File "/opt/nbproject/apps/rpc/views.py", line 808, in run
    r.content = getattr(MODULE, fctname)(payload, req)
  File "/opt/nbproject/apps/rpc/views.py", line 310, in getObjects
    output[t] = getattr(annotations, "get_"+t)(uid, p2)
  File "/opt/nbproject/apps/base/annotations.py", line 275, in get_file_stats
    return  db.Db().getIndexedObjects(names, "id", from_clause, "true" , (uid,uid, uid, uid, id_ensemble))
  File "/opt/nbproject/apps/base/db.py", line 127, in getIndexedObjects
    c = self.execute(qry, args, connection)
  File "/opt/nbproject/apps/base/db.py", line 49, in execute
    cursor.execute(qry, args)
  File "/usr/local/lib/python2.7/dist-packages/django/db/backends/utils.py", line 64, in execute
    return self.cursor.execute(sql, params)
  File "/usr/local/lib/python2.7/dist-packages/django/db/utils.py", line 95, in __exit__
    six.reraise(dj_exc_type, dj_exc_value, traceback)
  File "/usr/local/lib/python2.7/dist-packages/django/db/backends/utils.py", line 64, in execute
    return self.cursor.execute(sql, params)
ProgrammingError: relation "base_v_comment" does not exist
LINE 2: from base_v_comment vc left join (select distinct comment_id...
             ^

ERROR 2016-05-09 09:39:54,944 base 14169 140658464782144 Internal Server Error: /pdf4/rpc
Traceback (most recent call last):
  File "/usr/local/lib/python2.7/dist-packages/django/core/handlers/base.py", line 149, in get_response
    response = self.process_exception_by_middleware(e, request)
  File "/usr/local/lib/python2.7/dist-packages/django/core/handlers/base.py", line 147, in get_response
    response = wrapped_callback(request, *callback_args, **callback_kwargs)
  File "/usr/local/lib/python2.7/dist-packages/django/views/decorators/csrf.py", line 58, in wrapped_view
    return view_func(*args, **kwargs)
  File "/opt/nbproject/apps/rpc/views.py", line 808, in run
    r.content = getattr(MODULE, fctname)(payload, req)
  File "/opt/nbproject/apps/rpc/views.py", line 310, in getObjects
    output[t] = getattr(annotations, "get_"+t)(uid, p2)
  File "/opt/nbproject/apps/base/annotations.py", line 275, in get_file_stats
    return  db.Db().getIndexedObjects(names, "id", from_clause, "true" , (uid,uid, uid, uid, id_ensemble))
  File "/opt/nbproject/apps/base/db.py", line 127, in getIndexedObjects
    c = self.execute(qry, args, connection)
  File "/opt/nbproject/apps/base/db.py", line 49, in execute
    cursor.execute(qry, args)
  File "/usr/local/lib/python2.7/dist-packages/django/db/backends/utils.py", line 64, in execute
    return self.cursor.execute(sql, params)
  File "/usr/local/lib/python2.7/dist-packages/django/db/utils.py", line 95, in __exit__
    six.reraise(dj_exc_type, dj_exc_value, traceback)
  File "/usr/local/lib/python2.7/dist-packages/django/db/backends/utils.py", line 64, in execute
    return self.cursor.execute(sql, params)
ProgrammingError: relation "base_v_comment" does not exist
LINE 2: from base_v_comment vc left join (select distinct comment_id...
             ^

ERROR 2016-05-09 09:41:46,556 base 14169 140658464782144 Internal Server Error: /pdf4/rpc
Traceback (most recent call last):
  File "/usr/local/lib/python2.7/dist-packages/django/core/handlers/base.py", line 149, in get_response
    response = self.process_exception_by_middleware(e, request)
  File "/usr/local/lib/python2.7/dist-packages/django/core/handlers/base.py", line 147, in get_response
    response = wrapped_callback(request, *callback_args, **callback_kwargs)
  File "/usr/local/lib/python2.7/dist-packages/django/views/decorators/csrf.py", line 58, in wrapped_view
    return view_func(*args, **kwargs)
  File "/opt/nbproject/apps/rpc/views.py", line 808, in run
    r.content = getattr(MODULE, fctname)(payload, req)
  File "/opt/nbproject/apps/rpc/views.py", line 310, in getObjects
    output[t] = getattr(annotations, "get_"+t)(uid, p2)
  File "/opt/nbproject/apps/base/annotations.py", line 275, in get_file_stats
    return  db.Db().getIndexedObjects(names, "id", from_clause, "true" , (uid,uid, uid, uid, id_ensemble))
  File "/opt/nbproject/apps/base/db.py", line 127, in getIndexedObjects
    c = self.execute(qry, args, connection)
  File "/opt/nbproject/apps/base/db.py", line 49, in execute
    cursor.execute(qry, args)
  File "/usr/local/lib/python2.7/dist-packages/django/db/backends/utils.py", line 64, in execute
    return self.cursor.execute(sql, params)
  File "/usr/local/lib/python2.7/dist-packages/django/db/utils.py", line 95, in __exit__
    six.reraise(dj_exc_type, dj_exc_value, traceback)
  File "/usr/local/lib/python2.7/dist-packages/django/db/backends/utils.py", line 64, in execute
    return self.cursor.execute(sql, params)
ProgrammingError: relation "base_v_comment" does not exist
LINE 2: from base_v_comment vc left join (select distinct comment_id...
             ^

ERROR 2016-05-09 12:55:26,612 base 14169 140658464782144 Internal Server Error: /pdf4/rpc
Traceback (most recent call last):
  File "/usr/local/lib/python2.7/dist-packages/django/core/handlers/base.py", line 149, in get_response
    response = self.process_exception_by_middleware(e, request)
  File "/usr/local/lib/python2.7/dist-packages/django/core/handlers/base.py", line 147, in get_response
    response = wrapped_callback(request, *callback_args, **callback_kwargs)
  File "/usr/local/lib/python2.7/dist-packages/django/views/decorators/csrf.py", line 58, in wrapped_view
    return view_func(*args, **kwargs)
  File "/opt/nbproject/apps/rpc/views.py", line 808, in run
    r.content = getattr(MODULE, fctname)(payload, req)
  File "/opt/nbproject/apps/rpc/views.py", line 310, in getObjects
    output[t] = getattr(annotations, "get_"+t)(uid, p2)
  File "/opt/nbproject/apps/base/annotations.py", line 275, in get_file_stats
    return  db.Db().getIndexedObjects(names, "id", from_clause, "true" , (uid,uid, uid, uid, id_ensemble))
  File "/opt/nbproject/apps/base/db.py", line 127, in getIndexedObjects
    c = self.execute(qry, args, connection)
  File "/opt/nbproject/apps/base/db.py", line 49, in execute
    cursor.execute(qry, args)
  File "/usr/local/lib/python2.7/dist-packages/django/db/backends/utils.py", line 64, in execute
    return self.cursor.execute(sql, params)
  File "/usr/local/lib/python2.7/dist-packages/django/db/utils.py", line 95, in __exit__
    six.reraise(dj_exc_type, dj_exc_value, traceback)
  File "/usr/local/lib/python2.7/dist-packages/django/db/backends/utils.py", line 64, in execute
    return self.cursor.execute(sql, params)
ProgrammingError: relation "base_v_comment" does not exist
LINE 2: from base_v_comment vc left join (select distinct comment_id...
             ^

ERROR 2016-05-09 13:37:33,475 base 14169 140658464782144 Internal Server Error: /pdf4/rpc
Traceback (most recent call last):
  File "/usr/local/lib/python2.7/dist-packages/django/core/handlers/base.py", line 149, in get_response
    response = self.process_exception_by_middleware(e, request)
  File "/usr/local/lib/python2.7/dist-packages/django/core/handlers/base.py", line 147, in get_response
    response = wrapped_callback(request, *callback_args, **callback_kwargs)
  File "/usr/local/lib/python2.7/dist-packages/django/views/decorators/csrf.py", line 58, in wrapped_view
    return view_func(*args, **kwargs)
  File "/opt/nbproject/apps/rpc/views.py", line 808, in run
    r.content = getattr(MODULE, fctname)(payload, req)
  File "/opt/nbproject/apps/rpc/views.py", line 310, in getObjects
    output[t] = getattr(annotations, "get_"+t)(uid, p2)
  File "/opt/nbproject/apps/base/annotations.py", line 275, in get_file_stats
    return  db.Db().getIndexedObjects(names, "id", from_clause, "true" , (uid,uid, uid, uid, id_ensemble))
  File "/opt/nbproject/apps/base/db.py", line 127, in getIndexedObjects
    c = self.execute(qry, args, connection)
  File "/opt/nbproject/apps/base/db.py", line 49, in execute
    cursor.execute(qry, args)
  File "/usr/local/lib/python2.7/dist-packages/django/db/backends/utils.py", line 64, in execute
    return self.cursor.execute(sql, params)
  File "/usr/local/lib/python2.7/dist-packages/django/db/utils.py", line 95, in __exit__
    six.reraise(dj_exc_type, dj_exc_value, traceback)
  File "/usr/local/lib/python2.7/dist-packages/django/db/backends/utils.py", line 64, in execute
    return self.cursor.execute(sql, params)
ProgrammingError: relation "base_v_comment" does not exist
LINE 2: from base_v_comment vc left join (select distinct comment_id...
             ^

ERROR 2016-05-09 13:39:32,328 base 14169 140658464782144 Internal Server Error: /pdf4/rpc
Traceback (most recent call last):
  File "/usr/local/lib/python2.7/dist-packages/django/core/handlers/base.py", line 149, in get_response
    response = self.process_exception_by_middleware(e, request)
  File "/usr/local/lib/python2.7/dist-packages/django/core/handlers/base.py", line 147, in get_response
    response = wrapped_callback(request, *callback_args, **callback_kwargs)
  File "/usr/local/lib/python2.7/dist-packages/django/views/decorators/csrf.py", line 58, in wrapped_view
    return view_func(*args, **kwargs)
  File "/opt/nbproject/apps/rpc/views.py", line 808, in run
    r.content = getattr(MODULE, fctname)(payload, req)
  File "/opt/nbproject/apps/rpc/views.py", line 310, in getObjects
    output[t] = getattr(annotations, "get_"+t)(uid, p2)
  File "/opt/nbproject/apps/base/annotations.py", line 275, in get_file_stats
    return  db.Db().getIndexedObjects(names, "id", from_clause, "true" , (uid,uid, uid, uid, id_ensemble))
  File "/opt/nbproject/apps/base/db.py", line 127, in getIndexedObjects
    c = self.execute(qry, args, connection)
  File "/opt/nbproject/apps/base/db.py", line 49, in execute
    cursor.execute(qry, args)
  File "/usr/local/lib/python2.7/dist-packages/django/db/backends/utils.py", line 64, in execute
    return self.cursor.execute(sql, params)
  File "/usr/local/lib/python2.7/dist-packages/django/db/utils.py", line 95, in __exit__
    six.reraise(dj_exc_type, dj_exc_value, traceback)
  File "/usr/local/lib/python2.7/dist-packages/django/db/backends/utils.py", line 64, in execute
    return self.cursor.execute(sql, params)
ProgrammingError: relation "base_v_comment" does not exist
LINE 2: from base_v_comment vc left join (select distinct comment_id...
             ^

ERROR 2016-05-09 14:28:58,793 base 14169 140658464782144 Internal Server Error: /pdf4/rpc
Traceback (most recent call last):
  File "/usr/local/lib/python2.7/dist-packages/django/core/handlers/base.py", line 149, in get_response
    response = self.process_exception_by_middleware(e, request)
  File "/usr/local/lib/python2.7/dist-packages/django/core/handlers/base.py", line 147, in get_response
    response = wrapped_callback(request, *callback_args, **callback_kwargs)
  File "/usr/local/lib/python2.7/dist-packages/django/views/decorators/csrf.py", line 58, in wrapped_view
    return view_func(*args, **kwargs)
  File "/opt/nbproject/apps/rpc/views.py", line 808, in run
    r.content = getattr(MODULE, fctname)(payload, req)
  File "/opt/nbproject/apps/rpc/views.py", line 310, in getObjects
    output[t] = getattr(annotations, "get_"+t)(uid, p2)
  File "/opt/nbproject/apps/base/annotations.py", line 275, in get_file_stats
    return  db.Db().getIndexedObjects(names, "id", from_clause, "true" , (uid,uid, uid, uid, id_ensemble))
  File "/opt/nbproject/apps/base/db.py", line 127, in getIndexedObjects
    c = self.execute(qry, args, connection)
  File "/opt/nbproject/apps/base/db.py", line 49, in execute
    cursor.execute(qry, args)
  File "/usr/local/lib/python2.7/dist-packages/django/db/backends/utils.py", line 64, in execute
    return self.cursor.execute(sql, params)
  File "/usr/local/lib/python2.7/dist-packages/django/db/utils.py", line 95, in __exit__
    six.reraise(dj_exc_type, dj_exc_value, traceback)
  File "/usr/local/lib/python2.7/dist-packages/django/db/backends/utils.py", line 64, in execute
    return self.cursor.execute(sql, params)
ProgrammingError: relation "base_v_comment" does not exist
LINE 2: from base_v_comment vc left join (select distinct comment_id...
             ^

ERROR 2016-05-09 15:05:45,867 base 14169 140658464782144 Internal Server Error: /pdf4/rpc
Traceback (most recent call last):
  File "/usr/local/lib/python2.7/dist-packages/django/core/handlers/base.py", line 149, in get_response
    response = self.process_exception_by_middleware(e, request)
  File "/usr/local/lib/python2.7/dist-packages/django/core/handlers/base.py", line 147, in get_response
    response = wrapped_callback(request, *callback_args, **callback_kwargs)
  File "/usr/local/lib/python2.7/dist-packages/django/views/decorators/csrf.py", line 58, in wrapped_view
    return view_func(*args, **kwargs)
  File "/opt/nbproject/apps/rpc/views.py", line 808, in run
    r.content = getattr(MODULE, fctname)(payload, req)
  File "/opt/nbproject/apps/rpc/views.py", line 310, in getObjects
    output[t] = getattr(annotations, "get_"+t)(uid, p2)
  File "/opt/nbproject/apps/base/annotations.py", line 275, in get_file_stats
    return  db.Db().getIndexedObjects(names, "id", from_clause, "true" , (uid,uid, uid, uid, id_ensemble))
  File "/opt/nbproject/apps/base/db.py", line 127, in getIndexedObjects
    c = self.execute(qry, args, connection)
  File "/opt/nbproject/apps/base/db.py", line 49, in execute
    cursor.execute(qry, args)
  File "/usr/local/lib/python2.7/dist-packages/django/db/backends/utils.py", line 64, in execute
    return self.cursor.execute(sql, params)
  File "/usr/local/lib/python2.7/dist-packages/django/db/utils.py", line 95, in __exit__
    six.reraise(dj_exc_type, dj_exc_value, traceback)
  File "/usr/local/lib/python2.7/dist-packages/django/db/backends/utils.py", line 64, in execute
    return self.cursor.execute(sql, params)
ProgrammingError: relation "base_v_comment" does not exist
LINE 2: from base_v_comment vc left join (select distinct comment_id...
             ^

ERROR 2016-05-09 15:06:32,720 base 14169 140658464782144 Internal Server Error: /pdf4/rpc
Traceback (most recent call last):
  File "/usr/local/lib/python2.7/dist-packages/django/core/handlers/base.py", line 149, in get_response
    response = self.process_exception_by_middleware(e, request)
  File "/usr/local/lib/python2.7/dist-packages/django/core/handlers/base.py", line 147, in get_response
    response = wrapped_callback(request, *callback_args, **callback_kwargs)
  File "/usr/local/lib/python2.7/dist-packages/django/views/decorators/csrf.py", line 58, in wrapped_view
    return view_func(*args, **kwargs)
  File "/opt/nbproject/apps/rpc/views.py", line 808, in run
    r.content = getattr(MODULE, fctname)(payload, req)
  File "/opt/nbproject/apps/rpc/views.py", line 310, in getObjects
    output[t] = getattr(annotations, "get_"+t)(uid, p2)
  File "/opt/nbproject/apps/base/annotations.py", line 275, in get_file_stats
    return  db.Db().getIndexedObjects(names, "id", from_clause, "true" , (uid,uid, uid, uid, id_ensemble))
  File "/opt/nbproject/apps/base/db.py", line 127, in getIndexedObjects
    c = self.execute(qry, args, connection)
  File "/opt/nbproject/apps/base/db.py", line 49, in execute
    cursor.execute(qry, args)
  File "/usr/local/lib/python2.7/dist-packages/django/db/backends/utils.py", line 64, in execute
    return self.cursor.execute(sql, params)
  File "/usr/local/lib/python2.7/dist-packages/django/db/utils.py", line 95, in __exit__
    six.reraise(dj_exc_type, dj_exc_value, traceback)
  File "/usr/local/lib/python2.7/dist-packages/django/db/backends/utils.py", line 64, in execute
    return self.cursor.execute(sql, params)
ProgrammingError: relation "base_v_comment" does not exist
LINE 2: from base_v_comment vc left join (select distinct comment_id...
             ^

ERROR 2016-05-10 11:16:07,696 base 14169 140658464782144 Internal Server Error: /pdf4/rpc
Traceback (most recent call last):
  File "/usr/local/lib/python2.7/dist-packages/django/core/handlers/base.py", line 149, in get_response
    response = self.process_exception_by_middleware(e, request)
  File "/usr/local/lib/python2.7/dist-packages/django/core/handlers/base.py", line 147, in get_response
    response = wrapped_callback(request, *callback_args, **callback_kwargs)
  File "/usr/local/lib/python2.7/dist-packages/django/views/decorators/csrf.py", line 58, in wrapped_view
    return view_func(*args, **kwargs)
  File "/opt/nbproject/apps/rpc/views.py", line 808, in run
    r.content = getattr(MODULE, fctname)(payload, req)
  File "/opt/nbproject/apps/rpc/views.py", line 310, in getObjects
    output[t] = getattr(annotations, "get_"+t)(uid, p2)
  File "/opt/nbproject/apps/base/annotations.py", line 275, in get_file_stats
    return  db.Db().getIndexedObjects(names, "id", from_clause, "true" , (uid,uid, uid, uid, id_ensemble))
  File "/opt/nbproject/apps/base/db.py", line 127, in getIndexedObjects
    c = self.execute(qry, args, connection)
  File "/opt/nbproject/apps/base/db.py", line 49, in execute
    cursor.execute(qry, args)
  File "/usr/local/lib/python2.7/dist-packages/django/db/backends/utils.py", line 64, in execute
    return self.cursor.execute(sql, params)
  File "/usr/local/lib/python2.7/dist-packages/django/db/utils.py", line 95, in __exit__
    six.reraise(dj_exc_type, dj_exc_value, traceback)
  File "/usr/local/lib/python2.7/dist-packages/django/db/backends/utils.py", line 64, in execute
    return self.cursor.execute(sql, params)
ProgrammingError: relation "base_v_comment" does not exist
LINE 2: from base_v_comment vc left join (select distinct comment_id...
             ^

ERROR 2016-05-10 11:38:44,814 base 14169 140658464782144 Internal Server Error: /pdf4/rpc
Traceback (most recent call last):
  File "/usr/local/lib/python2.7/dist-packages/django/core/handlers/base.py", line 149, in get_response
    response = self.process_exception_by_middleware(e, request)
  File "/usr/local/lib/python2.7/dist-packages/django/core/handlers/base.py", line 147, in get_response
    response = wrapped_callback(request, *callback_args, **callback_kwargs)
  File "/usr/local/lib/python2.7/dist-packages/django/views/decorators/csrf.py", line 58, in wrapped_view
    return view_func(*args, **kwargs)
  File "/opt/nbproject/apps/rpc/views.py", line 808, in run
    r.content = getattr(MODULE, fctname)(payload, req)
  File "/opt/nbproject/apps/rpc/views.py", line 310, in getObjects
    output[t] = getattr(annotations, "get_"+t)(uid, p2)
  File "/opt/nbproject/apps/base/annotations.py", line 275, in get_file_stats
    return  db.Db().getIndexedObjects(names, "id", from_clause, "true" , (uid,uid, uid, uid, id_ensemble))
  File "/opt/nbproject/apps/base/db.py", line 127, in getIndexedObjects
    c = self.execute(qry, args, connection)
  File "/opt/nbproject/apps/base/db.py", line 49, in execute
    cursor.execute(qry, args)
  File "/usr/local/lib/python2.7/dist-packages/django/db/backends/utils.py", line 64, in execute
    return self.cursor.execute(sql, params)
  File "/usr/local/lib/python2.7/dist-packages/django/db/utils.py", line 95, in __exit__
    six.reraise(dj_exc_type, dj_exc_value, traceback)
  File "/usr/local/lib/python2.7/dist-packages/django/db/backends/utils.py", line 64, in execute
    return self.cursor.execute(sql, params)
ProgrammingError: relation "base_v_comment" does not exist
LINE 2: from base_v_comment vc left join (select distinct comment_id...
             ^

ERROR 2016-05-10 12:07:47,850 base 14169 140658464782144 Internal Server Error: /pdf4/rpc
Traceback (most recent call last):
  File "/usr/local/lib/python2.7/dist-packages/django/core/handlers/base.py", line 149, in get_response
    response = self.process_exception_by_middleware(e, request)
  File "/usr/local/lib/python2.7/dist-packages/django/core/handlers/base.py", line 147, in get_response
    response = wrapped_callback(request, *callback_args, **callback_kwargs)
  File "/usr/local/lib/python2.7/dist-packages/django/views/decorators/csrf.py", line 58, in wrapped_view
    return view_func(*args, **kwargs)
  File "/opt/nbproject/apps/rpc/views.py", line 808, in run
    r.content = getattr(MODULE, fctname)(payload, req)
  File "/opt/nbproject/apps/rpc/views.py", line 310, in getObjects
    output[t] = getattr(annotations, "get_"+t)(uid, p2)
  File "/opt/nbproject/apps/base/annotations.py", line 275, in get_file_stats
    return  db.Db().getIndexedObjects(names, "id", from_clause, "true" , (uid,uid, uid, uid, id_ensemble))
  File "/opt/nbproject/apps/base/db.py", line 127, in getIndexedObjects
    c = self.execute(qry, args, connection)
  File "/opt/nbproject/apps/base/db.py", line 49, in execute
    cursor.execute(qry, args)
  File "/usr/local/lib/python2.7/dist-packages/django/db/backends/utils.py", line 64, in execute
    return self.cursor.execute(sql, params)
  File "/usr/local/lib/python2.7/dist-packages/django/db/utils.py", line 95, in __exit__
    six.reraise(dj_exc_type, dj_exc_value, traceback)
  File "/usr/local/lib/python2.7/dist-packages/django/db/backends/utils.py", line 64, in execute
    return self.cursor.execute(sql, params)
ProgrammingError: relation "base_v_comment" does not exist
LINE 2: from base_v_comment vc left join (select distinct comment_id...
             ^

ERROR 2016-05-10 12:11:23,437 base 14169 140658464782144 Internal Server Error: /pdf4/rpc
Traceback (most recent call last):
  File "/usr/local/lib/python2.7/dist-packages/django/core/handlers/base.py", line 149, in get_response
    view_name = callback.__class__.__name__ + '.__call__'
  File "/usr/local/lib/python2.7/dist-packages/django/core/handlers/base.py", line 147, in get_response
    view_name = callback.__name__
  File "/usr/local/lib/python2.7/dist-packages/django/views/decorators/csrf.py", line 58, in wrapped_view
    return view_func(*args, **kwargs)
  File "/opt/nbproject/apps/rpc/views.py", line 808, in run
    r.content = getattr(MODULE, fctname)(payload, req)
  File "/opt/nbproject/apps/rpc/views.py", line 310, in getObjects
    output[t] = getattr(annotations, "get_"+t)(uid, p2)
  File "/opt/nbproject/apps/base/annotations.py", line 275, in get_file_stats
    return  db.Db().getIndexedObjects(names, "id", from_clause, "true" , (uid,uid, uid, uid, id_ensemble))
  File "/opt/nbproject/apps/base/db.py", line 127, in getIndexedObjects
    c = self.execute(qry, args, connection)
  File "/opt/nbproject/apps/base/db.py", line 49, in execute
    cursor.execute(qry, args)
  File "/usr/local/lib/python2.7/dist-packages/django/db/backends/utils.py", line 64, in execute
    return self.cursor.execute(sql, params)
  File "/usr/local/lib/python2.7/dist-packages/django/db/utils.py", line 95, in __exit__
    # the connection unusable.
  File "/usr/local/lib/python2.7/dist-packages/django/db/backends/utils.py", line 64, in execute
    return self.cursor.execute(sql, params)
ProgrammingError: relation "base_v_comment" does not exist
LINE 2: from base_v_comment vc left join (select distinct comment_id...
             ^

ERROR 2016-05-10 12:19:47,800 base 14169 140658464782144 Internal Server Error: /addyoutube/4
Traceback (most recent call last):
  File "/usr/local/lib/python2.7/dist-packages/django/core/handlers/base.py", line 149, in get_response
    view_name = callback.__class__.__name__ + '.__call__'
  File "/usr/local/lib/python2.7/dist-packages/django/core/handlers/base.py", line 147, in get_response
    view_name = callback.__name__
  File "/opt/nbproject/apps/pages/views.py", line 292, in add_youtube_doc
    ginfo = youtube.videos().list(part="id,contentDetails,snippet", id=key).execute()
  File "/usr/local/lib/python2.7/dist-packages/oauth2client/util.py", line 137, in positional_wrapper
    return wrapped(*args, **kwargs)
  File "/usr/local/lib/python2.7/dist-packages/googleapiclient/http.py", line 760, in execute
    raise HttpError(resp, content, uri=self.uri)
HttpError: <HttpError 400 when requesting https://www.googleapis.com/youtube/v3/videos?alt=json&part=id%2CcontentDetails%2Csnippet&id=_BLIWaEXIvc&key=CHANGE_ME returned "Bad Request">
ERROR 2016-05-10 12:20:02,322 base 14169 140658464782144 Internal Server Error: /addyoutube/4
Traceback (most recent call last):
  File "/usr/local/lib/python2.7/dist-packages/django/core/handlers/base.py", line 149, in get_response
    view_name = callback.__class__.__name__ + '.__call__'
  File "/usr/local/lib/python2.7/dist-packages/django/core/handlers/base.py", line 147, in get_response
    view_name = callback.__name__
  File "/opt/nbproject/apps/pages/views.py", line 292, in add_youtube_doc
    ginfo = youtube.videos().list(part="id,contentDetails,snippet", id=key).execute()
  File "/usr/local/lib/python2.7/dist-packages/oauth2client/util.py", line 137, in positional_wrapper
    return wrapped(*args, **kwargs)
  File "/usr/local/lib/python2.7/dist-packages/googleapiclient/http.py", line 760, in execute
    raise HttpError(resp, content, uri=self.uri)
HttpError: <HttpError 400 when requesting https://www.googleapis.com/youtube/v3/videos?alt=json&part=id%2CcontentDetails%2Csnippet&id=_BLIWaEXIvc&key=CHANGE_ME returned "Bad Request">
ERROR 2016-05-10 12:20:56,430 base 14169 140658464782144 Internal Server Error: /addyoutube/4
Traceback (most recent call last):
  File "/usr/local/lib/python2.7/dist-packages/django/core/handlers/base.py", line 149, in get_response
    view_name = callback.__class__.__name__ + '.__call__'
  File "/usr/local/lib/python2.7/dist-packages/django/core/handlers/base.py", line 147, in get_response
    view_name = callback.__name__
  File "/opt/nbproject/apps/pages/views.py", line 292, in add_youtube_doc
    ginfo = youtube.videos().list(part="id,contentDetails,snippet", id=key).execute()
  File "/usr/local/lib/python2.7/dist-packages/oauth2client/util.py", line 137, in positional_wrapper
    return wrapped(*args, **kwargs)
  File "/usr/local/lib/python2.7/dist-packages/googleapiclient/http.py", line 760, in execute
    raise HttpError(resp, content, uri=self.uri)
HttpError: <HttpError 400 when requesting https://www.googleapis.com/youtube/v3/videos?alt=json&part=id%2CcontentDetails%2Csnippet&id=_BLIWaEXIvc&key=CHANGE_ME returned "Bad Request">
ERROR 2016-05-10 12:21:26,212 base 14169 140658464782144 Internal Server Error: /pdf4/rpc
Traceback (most recent call last):
  File "/usr/local/lib/python2.7/dist-packages/django/core/handlers/base.py", line 149, in get_response
    view_name = callback.__class__.__name__ + '.__call__'
  File "/usr/local/lib/python2.7/dist-packages/django/core/handlers/base.py", line 147, in get_response
    view_name = callback.__name__
  File "/usr/local/lib/python2.7/dist-packages/django/views/decorators/csrf.py", line 58, in wrapped_view
    return view_func(*args, **kwargs)
  File "/opt/nbproject/apps/rpc/views.py", line 808, in run
    r.content = getattr(MODULE, fctname)(payload, req)
  File "/opt/nbproject/apps/rpc/views.py", line 310, in getObjects
    output[t] = getattr(annotations, "get_"+t)(uid, p2)
  File "/opt/nbproject/apps/base/annotations.py", line 275, in get_file_stats
    return  db.Db().getIndexedObjects(names, "id", from_clause, "true" , (uid,uid, uid, uid, id_ensemble))
  File "/opt/nbproject/apps/base/db.py", line 127, in getIndexedObjects
    c = self.execute(qry, args, connection)
  File "/opt/nbproject/apps/base/db.py", line 49, in execute
    cursor.execute(qry, args)
  File "/usr/local/lib/python2.7/dist-packages/django/db/backends/utils.py", line 64, in execute
    return self.cursor.execute(sql, params)
  File "/usr/local/lib/python2.7/dist-packages/django/db/utils.py", line 95, in __exit__
    # the connection unusable.
  File "/usr/local/lib/python2.7/dist-packages/django/db/backends/utils.py", line 64, in execute
    return self.cursor.execute(sql, params)
ProgrammingError: relation "base_v_comment" does not exist
LINE 2: from base_v_comment vc left join (select distinct comment_id...
             ^

